Workbook

Sheet DEC-24
A2: MONTH | B2: 45627
D3: KAYE | F3: SIKASSO | H3: SEGOU | J3: KUTIALLA | L3: MOPTI | N3: TOTAL
B4: PRODUCT NAME | C4: CIF | D4: Unit | E4: value | F4: Unit | G4: Value | H4: Unit | I4: Value | J4: Unit | K4: Value | L4: Unit | M4: Value | N4: Unit | O4: Value
A5: 1 | B5: AQUANATE | C5: 0.99 | D5: 2219 | E5: =D5*C5 -> 2196.81 | F5: 144 | G5: =F5*C5 -> 142.56 | H5: 5737 | I5: =H5*C5 -> 5679.63 | J5: 356 | K5: =J5*C5 -> 352.44 | L5: 4329 | M5: =L5*C5 -> 4285.71 | N5: =D5+F5+H5+J5+L5 -> 12785 | O5: =N5*C5 -> 12657.15
A6: 2 | B6: BACTOXIME SYRP | C6: 2.29 | D6: 102 | E6: =D6*C6 -> 233.58 | F6: 78 | G6: =F6*C6 -> 178.62 | H6: 97 | I6: =H6*C6 -> 222.13 | J6: 156 | K6: =J6*C6 -> 357.24 | L6: 102 | M6: =L6*C6 -> 233.58 | N6: =D6+F6+H6+J6+L6 -> 535 | O6: =N6*C6 -> 1225.15
A7: 3 | B7: BACTOXIME 200 | C7: 3.66 | D7: 116 | E7: =D7*C7 -> 424.56 | F7: 65 | G7: =F7*C7 -> 237.9 | H7: 204 | I7: =H7*C7 -> 746.64 | J7: 205 | K7: =J7*C7 -> 750.3 | L7: 180 | M7: =L7*C7 -> 658.8 | N7: =D7+F7+H7+J7+L7 -> 770 | O7: =N7*C7 -> 2818.2
A8: 4 | B8: ESOPRA 20 | C8: 2.81 | D8: 23 | E8: =D8*C8 -> 64.63 | F8: 8 | G8: =F8*C8 -> 22.48 | H8: 13 | I8: =H8*C8 -> 36.53 | J8: 5 | K8: =J8*C8 -> 14.05 | L8: 10 | M8: =L8*C8 -> 28.1 | N8: =D8+F8+H8+J8+L8 -> 59 | O8: =N8*C8 -> 165.79
A9: 5 | B9: ESOPRA 40 | C9: 3.46 | D9: 80 | E9: =D9*C9 -> 276.8 | F9: 20 | G9: =F9*C9 -> 69.2 | H9: 29 | I9: =H9*C9 -> 100.34 | J9: 10 | K9: =J9*C9 -> 34.6 | L9: 14 | M9: =L9*C9 -> 48.44 | N9: =D9+F9+H9+J9+L9 -> 153 | O9: =N9*C9 -> 529.38
A10: 6 | B10: METAREN | C10: 1.06 | D10: 27 | E10: =D10*C10 -> 28.62 | F10: 34 | G10: =F10*C10 -> 36.04 | H10: 22 | I10: =H10*C10 -> 23.32 | J10: 34 | K10: =J10*C10 -> 36.04 | L10: 52 | M10: =L10*C10 -> 55.12 | N10: =D10+F10+H10+J10+L10 -> 169 | O10: =N10*C10 -> 179.14
A11: 7 | B11: DIP3 | C11: 3.63 | D11: 8 | E11: =D11*C11 -> 29.04 | F11: ='UBIPHARM-OUTSTATION'!P11+'LABOREX OUTSTATION'!P11 -> 0 | G11: =F11*C11 -> 0 | H11: 0 | I11: =H11*C11 -> 0 | J11: 1 | K11: =J11*C11 -> 3.63 | L11: 10 | M11: =L11*C11 -> 36.3 | N11: =D11+F11+H11+J11+L11 -> 19 | O11: =N11*C11 -> 68.97
A12: 8 | B12: PALUCURE 20/120 | C12: 0.85 | D12: 0 | E12: =D12*C12 -> 0 | F12: 9 | G12: =F12*C12 -> 7.65 | H12: 3 | I12: =H12*C12 -> 2.55 | J12: 10 | K12: =J12*C12 -> 8.5 | L12: 12 | M12: =L12*C12 -> 10.2 | N12: =D12+F12+H12+J12+L12 -> 34 | O12: =N12*C12 -> 28.9
A13: 9 | B13: PALUCURE 80/480 | C13: 1.98 | D13: 246 | E13: =D13*C13 -> 487.08 | F13: 120 | G13: =F13*C13 -> 237.6 | H13: 164 | I13: =H13*C13 -> 324.72 | J13: 63 | K13: =J13*C13 -> 124.74 | L13: 174 | M13: =L13*C13 -> 344.52 | N13: =D13+F13+H13+J13+L13 -> 767 | O13: =N13*C13 -> 1518.66
A14: 10 | B14: PALUCURE 40/240 | C14: 1.98 | D14: 19 | E14: =D14*C14 -> 37.62 | F14: 13 | G14: =F14*C14 -> 25.74 | H14: 19 | I14: =H14*C14 -> 37.62 | J14: 21 | K14: =J14*C14 -> 41.58 | L14: 24 | M14: =L14*C14 -> 47.52 | N14: =D14+F14+H14+J14+L14 -> 96 | O14: =N14*C14 -> 190.08
A15: 11 | B15: TRACLAV1125 | C15: 4.69 | D15: 34 | E15: =D15*C15 -> 159.46 | F15: 18 | G15: =F15*C15 -> 84.42 | H15: 7 | I15: =H15*C15 -> 32.83 | J15: 10 | K15: =J15*C15 -> 46.9 | L15: 19 | M15: =L15*C15 -> 89.11 | N15: =D15+F15+H15+J15+L15 -> 88 | O15: =N15*C15 -> 412.72
A16: 12 | B16: TRACLAV 625 | C16: 2.9 | D16: 32 | E16: =D16*C16 -> 92.8 | F16: 8 | G16: =F16*C16 -> 23.2 | H16: 4 | I16: =H16*C16 -> 11.6 | J16: 13 | K16: =J16*C16 -> 37.7 | L16: 22 | M16: =L16*C16 -> 63.8 | N16: =D16+F16+H16+J16+L16 -> 79 | O16: =N16*C16 -> 229.1
A17: 13 | B17: TRACLAV 1.2 | C17: 1.5 | D17: 217 | E17: =D17*C17 -> 325.5 | F17: ='UBIPHARM-OUTSTATION'!P19+'LABOREX OUTSTATION'!P19 -> 0 | G17: =F17*C17 -> 0 | H17: 70 | I17: =H17*C17 -> 105 | J17: 14.5 | K17: =J17*C17 -> 21.75 | L17: 120 | M17: =L17*C17 -> 180 | N17: =D17+F17+H17+J17+L17 -> 421.5 | O17: =N17*C17 -> 632.25
B18: TOTAL | E18: =SUM(E5:E17) -> 4356.5 | G18: =SUM(G5:G17) -> 1065.41 | I18: =SUM(I5:I17) -> 7322.91 | K18: =SUM(K5:K17) -> 1829.47 | M18: =SUM(M5:M17) -> 6081.2 | O18: =SUM(E18+G18+I18+K18+M18) -> 20655.49

Sheet BAMAKO FINAL
A2: MONTH | B2: 45748
D3: COMMUNE 1 | F3: COMMUNE 2 | H3: TOTAL | J3: COMMUNE 3 | L3: COMMUNE 4 | N3: TOTAL | P3: COMMUNE 5 | R3: COMMUNE 6 | T3: KOULIKORO | V3: KATI | X3: TOTAL | Z3: BAMAKO/5
B4: PRODUCT NAME | C4: CIF | D4: Unit | E4: value | F4: Unit | G4: Value | H4: Unit | I4: Value | J4: Unit | K4: Value | L4: Unit | M4: Value | N4: Unit | O4: Value | P4: Unit | Q4: Value | R4: Unit | S4: Value | T4: Unit | U4: Value | V4: Unit | W4: Value | X4: Unit | Y4: Value | Z4: Unit | AA4: Value
A5: 1 | B5: AQUANATE | C5: 0.99 | D5: 1333 | E5: =D5*C5 -> 1319.67 | F5: 282 | G5: =F5*C5 -> 279.18 | H5: =D5+F5 -> 1615 | I5: =C5*H5 -> 1598.85 | J5: 862 | K5: =J5*C5 -> 853.38 | L5: 649 | M5: =L5*C5 -> 642.51 | N5: =J5+L5 -> 1511 | O5: =C5*N5 -> 1495.89 | P5: 1528 | Q5: =P5*C5 -> 1512.72 | R5: 1161 | S5: =R5*C5 -> 1149.39 | U5: =T5*C5 -> 0 | V5: 5850 | W5: =V5*C5 -> 5791.5 | X5: =D5+F5+J5+L5+P5+R5+T5+V5 -> 11665 | Y5: =X5*C5 -> 11548.35 | Z5: =X5/5 -> 2333 | AA5: =Z5*C5 -> 2309.67
A6: 2 | B6: BACTOXIME SYRP | C6: 2.29 | D6: 51 | E6: =D6*C6 -> 116.79 | F6: 15 | G6: =F6*C6 -> 34.35 | H6: =D6+F6 -> 66 | I6: =C6*H6 -> 151.14 | J6: 15 | K6: =J6*C6 -> 34.35 | L6: 59 | M6: =L6*C6 -> 135.11 | N6: =J6+L6 -> 74 | O6: =C6*N6 -> 169.46 | P6: 43 | Q6: =P6*C6 -> 98.47 | R6: 168 | S6: =R6*C6 -> 384.72 | U6: =T6*C6 -> 0 | V6: 35 | W6: =V6*C6 -> 80.15 | X6: =D6+F6+J6+L6+P6+R6+T6+V6 -> 386 | Y6: =X6*C6 -> 883.94 | Z6: =X6/5 -> 77.2 | AA6: =Z6*C6 -> 176.788
A7: 3 | B7: BACTOXIME 200 | C7: 3.66 | D7: 49 | E7: =D7*C7 -> 179.34 | F7: 18 | G7: =F7*C7 -> 65.88 | H7: =D7+F7 -> 67 | I7: =C7*H7 -> 245.22 | J7: 19 | K7: =J7*C7 -> 69.54 | L7: 25 | M7: =L7*C7 -> 91.5 | N7: =J7+L7 -> 44 | O7: =C7*N7 -> 161.04 | P7: 65 | Q7: =P7*C7 -> 237.9 | R7: 99 | S7: =R7*C7 -> 362.34 | U7: =T7*C7 -> 0 | V7: 72 | W7: =V7*C7 -> 263.52 | X7: =D7+F7+J7+L7+P7+R7+T7+V7 -> 347 | Y7: =X7*C7 -> 1270.02 | Z7: =X7/5 -> 69.4 | AA7: =Z7*C7 -> 254.004
A8: 4 | B8: ESOPRA 20 | C8: 2.81 | D8: 9 | E8: =D8*C8 -> 25.29 | F8: 10 | G8: =F8*C8 -> 28.1 | H8: =D8+F8 -> 19 | I8: =C8*H8 -> 53.39 | J8: 7 | K8: =J8*C8 -> 19.67 | L8: 16 | M8: =L8*C8 -> 44.96 | N8: =J8+L8 -> 23 | O8: =C8*N8 -> 64.63 | P8: 9 | Q8: =P8*C8 -> 25.29 | R8: 8 | S8: =R8*C8 -> 22.48 | U8: =T8*C8 -> 0 | V8: 5 | W8: =V8*C8 -> 14.05 | X8: =D8+F8+J8+L8+P8+R8+T8+V8 -> 64 | Y8: =X8*C8 -> 179.84 | Z8: =X8/5 -> 12.8 | AA8: =Z8*C8 -> 35.968
A9: 5 | B9: ESOPRA 40 | C9: 3.46 | D9: 18 | E9: =D9*C9 -> 62.28 | F9: 5 | G9: =F9*C9 -> 17.3 | H9: =D9+F9 -> 23 | I9: =C9*H9 -> 79.58 | J9: 20 | K9: =J9*C9 -> 69.2 | L9: 40 | M9: =L9*C9 -> 138.4 | N9: =J9+L9 -> 60 | O9: =C9*N9 -> 207.6 | P9: 38 | Q9: =P9*C9 -> 131.48 | R9: 43 | S9: =R9*C9 -> 148.78 | U9: =T9*C9 -> 0 | V9: 82 | W9: =V9*C9 -> 283.72 | X9: =D9+F9+J9+L9+P9+R9+T9+V9 -> 246 | Y9: =X9*C9 -> 851.16 | Z9: =X9/5 -> 49.2 | AA9: =Z9*C9 -> 170.232
A10: 6 | B10: METAREN | C10: 1.06 | D10: 86 | E10: =D10*C10 -> 91.16 | F10: 8 | G10: =F10*C10 -> 8.48 | H10: =D10+F10 -> 94 | I10: =C10*H10 -> 99.64 | J10: 6 | K10: =J10*C10 -> 6.36 | L10: 42 | M10: =L10*C10 -> 44.52 | N10: =J10+L10 -> 48 | O10: =C10*N10 -> 50.88 | P10: 60 | Q10: =P10*C10 -> 63.6 | R10: 66 | S10: =R10*C10 -> 69.96 | U10: =T10*C10 -> 0 | V10: 13 | W10: =V10*C10 -> 13.78 | X10: =D10+F10+J10+L10+P10+R10+T10+V10 -> 281 | Y10: =X10*C10 -> 297.86 | Z10: =X10/5 -> 56.2 | AA10: =Z10*C10 -> 59.572
A11: 7 | B11: DIP3 | C11: 3.63 | D11: 8 | E11: =D11*C11 -> 29.04 | F11: 1 | G11: =F11*C11 -> 3.63 | H11: =D11+F11 -> 9 | I11: =C11*H11 -> 32.67 | J11: 0 | K11: =J11*C11 -> 0 | L11: 0 | M11: =L11*C11 -> 0 | N11: =J11+L11 -> 0 | O11: =C11*N11 -> 0 | P11: 4 | Q11: =P11*C11 -> 14.52 | R11: 5 | S11: =R11*C11 -> 18.15 | U11: =T11*C11 -> 0 | V11: 0 | W11: =V11*C11 -> 0 | X11: =D11+F11+J11+L11+P11+R11+T11+V11 -> 18 | Y11: =X11*C11 -> 65.34 | Z11: =X11/5 -> 3.6 | AA11: =Z11*C11 -> 13.068
A12: 8 | B12: PALUCURE 20/120 | C12: 0.85 | D12: 4 | E12: =D12*C12 -> 3.4 | F12: 8 | G12: =F12*C12 -> 6.8 | H12: =D12+F12 -> 12 | I12: =C12*H12 -> 10.2 | J12: 47 | K12: =J12*C12 -> 39.95 | L12: 0 | M12: =L12*C12 -> 0 | N12: =J12+L12 -> 47 | O12: =C12*N12 -> 39.95 | P12: 45 | Q12: =P12*C12 -> 38.25 | R12: 7 | S12: =R12*C12 -> 5.95 | U12: =T12*C12 -> 0 | V12: 9 | W12: =V12*C12 -> 7.65 | X12: =D12+F12+J12+L12+P12+R12+T12+V12 -> 120 | Y12: =X12*C12 -> 102 | Z12: =X12/5 -> 24 | AA12: =Z12*C12 -> 20.4
A13: 9 | B13: PALUCURE 80/480 | C13: 1.98 | D13: 57 | E13: =D13*C13 -> 112.86 | F13: 33 | G13: =F13*C13 -> 65.34 | H13: =D13+F13 -> 90 | I13: =C13*H13 -> 178.2 | J13: 16 | K13: =J13*C13 -> 31.68 | L13: 51 | M13: =L13*C13 -> 100.98 | N13: =J13+L13 -> 67 | O13: =C13*N13 -> 132.66 | P13: 118 | Q13: =P13*C13 -> 233.64 | R13: 128 | S13: =R13*C13 -> 253.44 | U13: =T13*C13 -> 0 | V13: 121 | W13: =V13*C13 -> 239.58 | X13: =D13+F13+J13+L13+P13+R13+T13+V13 -> 524 | Y13: =X13*C13 -> 1037.52 | Z13: =X13/5 -> 104.8 | AA13: =Z13*C13 -> 207.504
A14: 10 | B14: PALUCURE 40/240 | C14: 1.98 | D14: 6 | E14: =D14*C14 -> 11.88 | F14: 2 | G14: =F14*C14 -> 3.96 | H14: =D14+F14 -> 8 | I14: =C14*H14 -> 15.84 | J14: 9 | K14: =J14*C14 -> 17.82 | L14: 14 | M14: =L14*C14 -> 27.72 | N14: =J14+L14 -> 23 | O14: =C14*N14 -> 45.54 | P14: 24 | Q14: =P14*C14 -> 47.52 | R14: 38 | S14: =R14*C14 -> 75.24 | U14: =T14*C14 -> 0 | V14: 21 | W14: =V14*C14 -> 41.58 | X14: =D14+F14+J14+L14+P14+R14+T14+V14 -> 114 | Y14: =X14*C14 -> 225.72 | Z14: =X14/5 -> 22.8 | AA14: =Z14*C14 -> 45.144
A15: 11 | B15: TRACLAV1125 | C15: 4.69 | D15: 17 | E15: =D15*C15 -> 79.73 | F15: 14 | G15: =F15*C15 -> 65.66 | H15: =D15+F15 -> 31 | I15: =C15*H15 -> 145.39 | J15: 4 | K15: =J15*C15 -> 18.76 | L15: 39 | M15: =L15*C15 -> 182.91 | N15: =J15+L15 -> 43 | O15: =C15*N15 -> 201.67 | P15: 82 | Q15: =P15*C15 -> 384.58 | R15: 142 | S15: =R15*C15 -> 665.98 | U15: =T15*C15 -> 0 | V15: 16 | W15: =V15*C15 -> 75.04 | X15: =D15+F15+J15+L15+P15+R15+T15+V15 -> 314 | Y15: =X15*C15 -> 1472.66 | Z15: =X15/5 -> 62.8 | AA15: =Z15*C15 -> 294.532
A16: 12 | B16: TRACLAV 625 | C16: 2.9 | D16: 27 | E16: =D16*C16 -> 78.3 | F16: 10 | G16: =F16*C16 -> 29 | H16: =D16+F16 -> 37 | I16: =C16*H16 -> 107.3 | J16: 5 | K16: =J16*C16 -> 14.5 | L16: 47 | M16: =L16*C16 -> 136.3 | N16: =J16+L16 -> 52 | O16: =C16*N16 -> 150.8 | P16: 36 | Q16: =P16*C16 -> 104.4 | R16: 36 | S16: =R16*C16 -> 104.4 | U16: =T16*C16 -> 0 | V16: 10 | W16: =V16*C16 -> 29 | X16: =D16+F16+J16+L16+P16+R16+T16+V16 -> 171 | Y16: =X16*C16 -> 495.9 | Z16: =X16/5 -> 34.2 | AA16: =Z16*C16 -> 99.18
A17: 13 | B17: TRACLAV 1.2 | C17: 1.5 | D17: 138 | E17: =D17*C17 -> 207 | F17: 0 | G17: =F17*C17 -> 0 | H17: =D17+F17 -> 138 | I17: =C17*H17 -> 207 | J17: 24 | K17: =J17*C17 -> 36 | L17: 122 | M17: =L17*C17 -> 183 | N17: =J17+L17 -> 146 | O17: =C17*N17 -> 219 | P17: 0 | Q17: =P17*C17 -> 0 | R17: 39 | S17: =R17*C17 -> 58.5 | U17: =T17*C17 -> 0 | V17: 146 | W17: =V17*C17 -> 219 | X17: =D17+F17+J17+L17+P17+R17+T17+V17 -> 469 | Y17: =X17*C17 -> 703.5 | Z17: =X17/5 -> 93.8 | AA17: =Z17*C17 -> 140.7
B18: TOTAL | E18: =SUM(E5:E17) -> 2316.74 | G18: =SUM(G5:G17) -> 607.68 | I18: =SUM(I5:I17) -> 2924.42 | K18: =SUM(K5:K17) -> 1211.21 | M18: =SUM(M5:M17) -> 1727.91 | O18: =SUM(O5:O17) -> 2939.12 | Q18: =SUM(Q5:Q17) -> 2892.37 | S18: =SUM(S5:S17) -> 3319.33 | U18: =SUM(U5:U17) -> 0 | W18: =SUM(W5:W17) -> 7058.57 | Y18: =I18+O18+Q18+S18+W18 -> 19133.81 | AA18: =SUM(AA5:AA17) -> 3826.762

Sheet BAMAKO POOL-UBIPHARM
A2: MONTH | B2: 45962 | D2: BAMAKO EST | H2: BAMAKO OUEST | L2: BAMAKO RIVE DROITE | R2: BAMAKO CENTRE
D3: COMMUNE 1 | F3: COMMUNE 2 | H3: COMMUNE 3 | J3: COMMUNE 4 | L3: COMMUNE 5 | N3: COMMUNE 6 | P3: KOULIKORO | R3: KATI | T3: TOTAL
B4: PRODUCT NAME | C4: CIF | D4: Unit | E4: value | F4: Unit | G4: Value | H4: Unit | I4: Value | J4: Unit | K4: Value | L4: Unit | M4: Value | N4: Unit | O4: Value | P4: Unit | Q4: Value | R4: Unit | S4: Value | T4: Unit | U4: Value
A5: 1 | B5: AQUANATE | C5: 0.99 | D5: 65 | E5: =D5*C5 -> 64.35 | G5: =F5*A5 -> 0 | H5: 142 | I5: =H5*C5 -> 140.58 | K5: =J5*C5 -> 0 | L5: 337 | M5: =L5*C5 -> 333.63 | N5: 700 | O5: =N5* C5 -> 693 | Q5: =P5*C5 -> 0 | R5: 3000 | S5: =R5*C5 -> 2970 | T5: =D5+F5+H5+J5+L5+N5+P5+R5 -> 4244 | U5: =T5*C5 -> 4201.56
A6: 2 | B6: BACTOXIME SYRP | C6: 2.29 | D6: 2 | E6: =D6*C6 -> 4.58 | G6: =F6*A6 -> 0 | H6: 5 | I6: =H6*C6 -> 11.45 | K6: =J6*C6 -> 0 | L6: 0 | M6: =L6*C6 -> 0 | N6: 1 | O6: =N6*C6 -> 2.29 | Q6: =P6*C6 -> 0 | R6: 0 | S6: =R6*C6 -> 0 | T6: =D6+F6+H6+J6+L6+N6+P6+R6 -> 8 | U6: =T6*C6 -> 18.32
A7: 3 | B7: BACTOXIME 200 | C7: 3.66 | D7: 54 | E7: =D7*C7 -> 197.64 | G7: =F7*A7 -> 0 | H7: 88 | I7: =H7*C7 -> 322.08 | K7: =J7*C7 -> 0 | L7: 120 | M7: =L7*C7 -> 439.2 | N7: 126 | O7: =N7*C7 -> 461.16 | Q7: =P7*C7 -> 0 | R7: 100 | S7: =R7*C7 -> 366 | T7: =D7+F7+H7+J7+L7+N7+P7+R7 -> 488 | U7: =T7*C7 -> 1786.08
A8: 4 | B8: ESOPRA 20 | C8: 2.81 | D8: 20 | E8: =D8*C8 -> 56.2 | G8: =F8*A8 -> 0 | H8: 22 | I8: =H8*C8 -> 61.82 | K8: =J8*C8 -> 0 | L8: 15 | M8: =L8*C8 -> 42.15 | N8: 16 | O8: =N8*C8 -> 44.96 | Q8: =P8*C8 -> 0 | R8: 20 | S8: =R8*C8 -> 56.2 | T8: =D8+F8+H8+J8+L8+N8+P8+R8 -> 93 | U8: =T8*C8 -> 261.33
A9: 5 | B9: ESOPRA 40 | C9: 3.46 | D9: 16 | E9: =D9*C9 -> 55.36 | G9: =F9*A9 -> 0 | H9: 25 | I9: =H9*C9 -> 86.5 | K9: =J9*C9 -> 0 | L9: 27 | M9: =L9*C9 -> 93.42 | N9: 27 | O9: =N9*C9 -> 93.42 | Q9: =P9*C9 -> 0 | R9: 30 | S9: =R9*C9 -> 103.8 | T9: =D9+F9+H9+J9+L9+N9+P9+R9 -> 125 | U9: =T9*C9 -> 432.5
A10: 6 | B10: METAREN | C10: 1.06 | D10: 0 | E10: =D10*C10 -> 0 | G10: =F10*A10 -> 0 | H10: 0 | I10: =H10*C10 -> 0 | K10: =J10*C10 -> 0 | L10: 0 | M10: =L10*C10 -> 0 | N10: 0 | O10: =N10*C10 -> 0 | Q10: =P10*C10 -> 0 | R10: 0 | S10: =R10*C10 -> 0 | T10: =D10+F10+H10+J10+L10+N10+P10+R10 -> 0 | U10: =T10*C10 -> 0
A11: 7 | B11: DIP3 | C11: 3.63 | D11: 0 | E11: =D11*C11 -> 0 | G11: =F11*A11 -> 0 | H11: 0 | I11: =H11*C11 -> 0 | K11: =J11*C11 -> 0 | L11: 0 | M11: =L11*C11 -> 0 | N11: 0 | O11: =N11*C11 -> 0 | Q11: =P11*C11 -> 0 | R11: 0 | S11: =R11*C11 -> 0 | T11: =D11+F11+H11+J11+L11+N11+P11+R11 -> 0 | U11: =T11*C11 -> 0
A12: 8 | B12: PALUCURE 20/120 | C12: 0.85 | D12: 9 | E12: =D12*C12 -> 7.65 | G12: =F12*A12 -> 0 | H12: 55 | I12: =H12*C12 -> 46.75 | K12: =J12*C12 -> 0 | L12: 22 | M12: =L12*C12 -> 18.7 | N12: 100 | O12: =N12*C12 -> 85 | Q12: =P12*C12 -> 0 | R12: 35 | S12: =R12*C12 -> 29.75 | T12: =D12+F12+H12+J12+L12+N12+P12+R12 -> 221 | U12: =T12*C12 -> 187.85
A13: 9 | B13: PALUCURE 80/480 | C13: 1.98 | D13: 53 | E13: =D13*C13 -> 104.94 | G13: =F13*A13 -> 0 | H13: 161 | I13: =H13*C13 -> 318.78 | K13: =J13*C13 -> 0 | L13: 83 | M13: =L13*C13 -> 164.34 | N13: 83 | O13: =N13*C13 -> 164.34 | Q13: =P13*C13 -> 0 | R13: 236 | S13: =R13*C13 -> 467.28 | T13: =D13+F13+H13+J13+L13+N13+P13+R13 -> 616 | U13: =T13*C13 -> 1219.68
A14: 10 | B14: PALUCURE 40/240 | C14: 1.98 | D14: 6 | E14: =D14*C14 -> 11.88 | G14: =F14*A14 -> 0 | H14: 32 | I14: =H14*C14 -> 63.36 | K14: =J14*C14 -> 0 | L14: 33 | M14: =L14*C14 -> 65.34 | N14: 70 | O14: =N14*C14 -> 138.6 | Q14: =P14*C14 -> 0 | R14: 52 | S14: =R14*C14 -> 102.96 | T14: =D14+F14+H14+J14+L14+N14+P14+R14 -> 193 | U14: =T14*C14 -> 382.14
A15: 11 | B15: TRACLAV1125 | C15: 4.69 | D15: 0 | E15: =D15*C15 -> 0 | G15: =F15*A15 -> 0 | H15: 0 | I15: =H15*C15 -> 0 | K15: =J15*C15 -> 0 | L15: 0 | M15: =L15*C15 -> 0 | N15: 0 | O15: =N15*C15 -> 0 | Q15: =P15*C15 -> 0 | R15: 0 | S15: =R15*C15 -> 0 | T15: =D15+F15+H15+J15+L15+N15+P15+R15 -> 0 | U15: =T15*C15 -> 0
A16: 12 | B16: TRACLAV 625 | C16: 2.9 | D16: 0 | E16: =D16*C16 -> 0 | G16: =F16*A16 -> 0 | H16: 0 | I16: =H16*C16 -> 0 | K16: =J16*C16 -> 0 | L16: 0 | M16: =L16*C16 -> 0 | N16: 0 | O16: =N16*C16 -> 0 | Q16: =P16*C16 -> 0 | R16: 0 | S16: =R16*C16 -> 0 | T16: =D16+F16+H16+J16+L16+N16+P16+R16 -> 0 | U16: =T16*C16 -> 0
A17: 13 | B17: TRIAF- S | C17: 1.9 | D17: 30 | E17: =D17*C17 -> 57 | G17: =F17*C17 -> 0 | H17: 40 | I17: =H17*C17 -> 76 | K17: =J17*C17 -> 0 | L17: 40 | M17: =L17*C17 -> 76 | N17: 60 | O17: =N17*C17 -> 114 | Q17: =P17*C17 -> 0 | R17: 40 | S17: =R17*C17 -> 76 | T17: =D17+F17+H17+J17+L17+N17+P17+R17 -> 210 | U17: =T17*C17 -> 399
A18: 14 | B18: PALUCURE PLUS 80/480 | C18: 2.4 | D18: 0 | E18: =D18*C18 -> 0 | G18: =F18*C18 -> 0 | H18: 0 | I18: =H18*C18 -> 0 | K18: =J18*C18 -> 0 | L18: 0 | M18: =L18*C18 -> 0 | N18: 0 | O18: =N18*C18 -> 0 | Q18: =P18*C18 -> 0 | R18: 0 | S18: =R18*C18 -> 0 | T18: =D18+F18+H18+J18+L18+N18+P18+R18 -> 0 | U18: =T18*C18 -> 0
A19: 15 | B19: TRACLAV 1.2 | C19: 1.5 | D19: 0 | E19: =D19*C19 -> 0 | G19: =F19*A19 -> 0 | H19: 0 | I19: =H19*C19 -> 0 | K19: =J19*C19 -> 0 | L19: 0 | M19: =L19*C19 -> 0 | N19: 0 | O19: =N19*C19 -> 0 | Q19: =P19*C19 -> 0 | R19: 0 | S19: =R19*C19 -> 0 | T19: =D19+F19+H19+J19+L19+N19+P19+R19 -> 0 | U19: =T19*C19 -> 0
A20: 16 | B20: TRACLAV1125 SACHT | C20: 5.38 | D20: 18 | E20: =D20*C20 -> 96.84 | G20: =F20*C20 -> 0 | H20: 9 | I20: =H20*C20 -> 48.42 | K20: =J20*C20 -> 0 | L20: 42 | M20: =L20*C20 -> 225.96 | N20: 43 | O20: =N20*C20 -> 231.34 | Q20: =P20*C20 -> 0 | R20: 16 | S20: =R20*C20 -> 86.08 | T20: =D20+F20+H20+J20+L20+N20+P20+R20 -> 128 | U20: =T20*C20 -> 688.64
A21: 17 | B21: TUMI | C21: 2 | D21: 0 | E21: =D21*C21 -> 0 | G21: 0 | H21: 0 | I21: =H21*C21 -> 0 | K21: =J21*C21 -> 0 | L21: 0 | M21: =L21*C21 -> 0 | N21: 0 | O21: =N21*C21 -> 0 | Q21: =P21*C21 -> 0 | R21: 0 | S21: =R21*C21 -> 0 | T21: =D21+F21+H21+J21+L21+N21+P21+R21 -> 0 | U21: =T21*C21 -> 0
B22: TOTAL | E22: =SUM(E5:E21) -> 656.44 | G22: =SUM(G5:G19) -> 0 | I22: =SUM(I5:I21) -> 1175.74 | K22: =SUM(K5:K19) -> 0 | M22: =SUM(M5:M21) -> 1458.74 | O22: =SUM(O5:O21) -> 2028.11 | Q22: =SUM(Q5:Q19) -> 0 | S22: =SUM(S5:S21) -> 4258.07 | U22: =SUM(U5:U21) -> 9577.1

Sheet BAMAKO POOL-LABOREX
A2: MONTH | B2: 45962
D3: COMMUNE 1 | F3: COMMUNE 2 | H3: COMMUNE 3 | J3: COMMUNE 4 | L3: COMMUNE 5 | N3: COMMUNE 6 | P3: KOULIKORO | R3: KATI | T3: TOTAL
B4: PRODUCT NAME | C4: CIF | D4: Unit | E4: value | F4: Unit | G4: Value | H4: Unit | I4: Value | J4: Unit | K4: Value | L4: Unit | M4: Value | N4: Unit | O4: Value | P4: Unit | Q4: Value | R4: Unit | S4: Value | T4: Unit | U4: Value
A5: 1 | B5: AQUANATE | C5: 0.99 | D5: 89 | E5: =D5*C5 -> 88.11 | F5: 114 | G5: =F5*A5 -> 114 | H5: 691 | I5: =H5*C5 -> 684.09 | J5: 317 | K5: =J5*C5 -> 313.83 | L5: 1296 | M5: =L5*C5 -> 1283.04 | N5: 3262 | O5: =N5*C5 -> 3229.38 | Q5: =P5*C5 -> 0 | R5: 1521 | S5: =R5*C5 -> 1505.79 | T5: =D5+F5+H5+J5+L5+N5+P5+R5 -> 7290 | U5: =T5*C5 -> 7217.1
A6: 2 | B6: BACTOXIME SYRP | C6: 2.29 | D6: 86 | E6: =D6*C6 -> 196.94 | F6: 70 | G6: =F6*A6 -> 140 | H6: 60 | I6: =H6*C6 -> 137.4 | J6: 58 | K6: =J6*C6 -> 132.82 | L6: 83 | M6: =L6*C6 -> 190.07 | N6: 167 | O6: =N6*C6 -> 382.43 | Q6: =P6*C6 -> 0 | R6: 32 | S6: =R6*C6 -> 73.28 | T6: =D6+F6+H6+J6+L6+N6+P6+R6 -> 556 | U6: =T6*C6 -> 1273.24
A7: 3 | B7: BACTOXIME 200 | C7: 3.66 | D7: 19 | E7: =D7*C7 -> 69.54 | F7: 8 | G7: =F7*C7 -> 29.28 | H7: 0 | I7: =H7*C7 -> 0 | J7: 8 | K7: =J7*C7 -> 29.28 | L7: 28 | M7: =L7*C7 -> 102.48 | N7: 35 | O7: =N7*C7 -> 128.1 | Q7: =P7*C7 -> 0 | R7: 4 | S7: =R7*C7 -> 14.64 | T7: =D7+F7+H7+J7+L7+N7+P7+R7 -> 102 | U7: =T7*C7 -> 373.32
A8: 4 | B8: ESOPRA 20 | C8: 2.81 | D8: 18 | E8: =D8*C8 -> 50.58 | F8: 21 | G8: =F8*C8 -> 59.01 | H8: 19 | I8: =H8*C8 -> 53.39 | J8: 25 | K8: =J8*C8 -> 70.25 | L8: 4 | M8: =L8*C8 -> 11.24 | N8: 9 | O8: =N8*C8 -> 25.29 | Q8: =P8*C8 -> 0 | R8: 12 | S8: =R8*C8 -> 33.72 | T8: =D8+F8+H8+J8+L8+N8+P8+R8 -> 108 | U8: =T8*C8 -> 303.48
A9: 5 | B9: ESOPRA 40 | C9: 3.46 | D9: 27 | E9: =D9*C9 -> 93.42 | F9: 35 | G9: =F9*C9 -> 121.1 | H9: 32 | I9: =H9*C9 -> 110.72 | J9: 36 | K9: =J9*C9 -> 124.56 | L9: 47 | M9: =L9*C9 -> 162.62 | N9: 65 | O9: =N9*C9 -> 224.9 | Q9: =P9*C9 -> 0 | R9: 45 | S9: =R9*C9 -> 155.7 | T9: =D9+F9+H9+J9+L9+N9+P9+R9 -> 287 | U9: =T9*C9 -> 993.02
A10: 6 | B10: METAREN | C10: 1.06 | D10: 0 | E10: =D10*C10 -> 0 | F10: 0 | G10: =F10*C10 -> 0 | H10: 0 | I10: =H10*C10 -> 0 | J10: 0 | K10: =J10*C10 -> 0 | L10: 0 | M10: =L10*C10 -> 0 | N10: 0 | O10: =N10*C10 -> 0 | Q10: =P10*C10 -> 0 | R10: 0 | S10: =R10*C10 -> 0 | T10: =D10+F10+H10+J10+L10+N10+P10+R10 -> 0 | U10: =T10*C10 -> 0
A11: 7 | B11: DIP3 | C11: 3.63 | D11: 0 | E11: =D11*C11 -> 0 | F11: 0 | G11: =F11*C11 -> 0 | H11: 0 | I11: =H11*C11 -> 0 | J11: 0 | K11: =J11*C11 -> 0 | L11: 0 | M11: =L11*C11 -> 0 | N11: 0 | O11: =N11*C11 -> 0 | Q11: =P11*C11 -> 0 | R11: 0 | S11: =R11*C11 -> 0 | T11: =D11+F11+H11+J11+L11+N11+P11+R11 -> 0 | U11: =T11*C11 -> 0
A12: 8 | B12: PALUCURE 20/120 | C12: 0.85 | D12: 0 | E12: =D12*C12 -> 0 | F12: 0 | G12: =F12*C12 -> 0 | H12: 0 | I12: =H12*C12 -> 0 | J12: 0 | K12: =J12*C12 -> 0 | L12: 0 | M12: =L12*C12 -> 0 | N12: 0 | O12: =N12*C12 -> 0 | Q12: =P12*C12 -> 0 | R12: 0 | S12: =R12*C12 -> 0 | T12: =D12+F12+H12+J12+L12+N12+P12+R12 -> 0 | U12: =T12*C12 -> 0
A13: 9 | B13: PALUCURE 80/480 | C13: 1.98 | D13: 55 | E13: =D13*C13 -> 108.9 | F13: 79 | G13: =F13*C13 -> 156.42 | H13: 68 | I13: =H13*C13 -> 134.64 | J13: 79 | K13: =J13*C13 -> 156.42 | L13: 140 | M13: =L13*C13 -> 277.2 | N13: 297 | O13: =N13*C13 -> 588.06 | Q13: =P13*C13 -> 0 | R13: 117 | S13: =R13*C13 -> 231.66 | T13: =D13+F13+H13+J13+L13+N13+P13+R13 -> 835 | U13: =T13*C13 -> 1653.3
A14: 10 | B14: PALUCURE 40/240 | C14: 1.98 | D14: 11 | E14: =D14*C14 -> 21.78 | F14: 7 | G14: =F14*C14 -> 13.86 | H14: 14 | I14: =H14*C14 -> 27.72 | J14: 8 | K14: =J14*C14 -> 15.84 | L14: 35 | M14: =L14*C14 -> 69.3 | N14: 66 | O14: =N14*C14 -> 130.68 | Q14: =P14*C14 -> 0 | R14: 21 | S14: =R14*C14 -> 41.58 | T14: =D14+F14+H14+J14+L14+N14+P14+R14 -> 162 | U14: =T14*C14 -> 320.76
A15: 11 | B15: TRACLAV1125 | C15: 4.69 | D15: 0 | E15: =D15*C15 -> 0 | F15: 0 | G15: =F15*C15 -> 0 | H15: 0 | I15: =H15*C15 -> 0 | J15: 0 | K15: =J15*C15 -> 0 | L15: 0 | M15: =L15*C15 -> 0 | N15: 0 | O15: =N15*C15 -> 0 | Q15: =P15*C15 -> 0 | R15: 0 | S15: =R15*C15 -> 0 | T15: =D15+F15+H15+J15+L15+N15+P15+R15 -> 0 | U15: =T15*C15 -> 0
A16: 12 | B16: TRACLAV 625 | C16: 2.9 | D16: 0 | E16: =D16*C16 -> 0 | F16: 0 | G16: =F16*C16 -> 0 | H16: 0 | I16: =H16*C16 -> 0 | J16: 0 | K16: =J16*C16 -> 0 | L16: 0 | M16: =L16*C16 -> 0 | N16: 0 | O16: =N16*C16 -> 0 | Q16: =P16*C16 -> 0 | R16: 0 | S16: =R16*C16 -> 0 | T16: =D16+F16+H16+J16+L16+N16+P16+R16 -> 0 | U16: =T16*C16 -> 0
A17: 13 | B17: TRIAF- S | C17: 1.9 | D17: 0 | E17: =D17*C17 -> 0 | F17: 0 | G17: =F17*C17 -> 0 | H17: 0 | I17: =H17*C17 -> 0 | J17: 0 | K17: =J17*C17 -> 0 | L17: 0 | M17: =L17*C17 -> 0 | N17: 0 | O17: =N17*C17 -> 0 | Q17: =P17*C17 -> 0 | R17: 0 | S17: =R17*C17 -> 0 | T17: =D17+F17+H17+J17+L17+N17+P17+R17 -> 0 | U17: =T17*C17 -> 0
A18: 14 | B18: PALUCURE PLUS 80/480 | C18: 2.4 | D18: 0 | E18: =D18*C18 -> 0 | F18: 0 | G18: =F18*C18 -> 0 | H18: 0 | I18: =H18*C18 -> 0 | J18: 0 | K18: =J18*C18 -> 0 | L18: 0 | M18: =L18*C18 -> 0 | N18: 0 | O18: =N18*C18 -> 0 | Q18: =P18*C18 -> 0 | R18: 0 | S18: =R18*C18 -> 0 | T18: =D18+F18+H18+J18+L18+N18+P18+R18 -> 0 | U18: =T18*C18 -> 0
... A20: 16 | B20: TRACLAV1125 SACHT | C20: 5.3 | D20: 26 | E20: =D20*C20 -> 137.8 | F20: 9 | G20: =F20*C20 -> 47.7 | H20: 4 | I20: =H20*C20 -> 21.2 | J20: 0 | K20: =J20*C20 -> 0 | L20: 23 | M20: =L20*C20 -> 121.9 | N20: 12 | O20: =N20*C20 -> 63.6 | Q20: =P20*C20 -> 0 | R20: 2 | S20: =R20*C20 -> 10.6 | T20: =D20+F20+H20+J20+L20+N20+P20+R20 -> 76 | U20: =T20*C20 -> 402.8
A21: 17 | B21: TUMI | C21: 2 | D21: 0 | E21: =D21*C21 -> 0 | F21: 0 | G21: =F21*A21 -> 0 | H21: 0 | I21: =H21*C21 -> 0 | J21: 0 | K21: =J21*C21 -> 0 | L21: 0 | M21: =L21*C21 -> 0 | N21: 0 | O21: =N21*C21 -> 0 | Q21: =P21*C21 -> 0 | R21: 0 | S21: =R21*C21 -> 0 | T21: =D21+F21+H21+J21+L21+N21+P21+R21 -> 0 | U21: =T21*C21 -> 0
B22: TOTAL | E22: =SUM(E5:E21) -> 767.07 | G22: =SUM(G5:G21) -> 681.37 | I22: =SUM(I5:I21) -> 1169.16 | K22: =SUM(K5:K21) -> 843 | M22: =SUM(M5:M21) -> 2217.85 | O22: =SUM(O5:O21) -> 4772.44 | Q22: =SUM(Q5:Q19) -> 0 | S22: =SUM(S5:S21) -> 2066.97 | U22: =SUM(U5:U21) -> 12537.02

Sheet BAMAKO POOL-AFRICALA
A2: MONTH | B2: 45627
D3: COMMUNE 1 | F3: COMMUNE 2 | H3: COMMUNE 3 | J3: COMMUNE 4 | L3: COMMUNE 5 | N3: COMMUNE 6 | P3: KOULIKORO | R3: KATI | T3: TOTAL
B4: PRODUCT NAME | C4: CIF | D4: Unit | E4: value | F4: Unit | G4: Value | H4: Unit | I4: Value | J4: Unit | K4: Value | L4: Unit | M4: Value | N4: Unit | O4: Value | P4: Unit | Q4: Value | R4: Unit | S4: Value | T4: Unit | U4: Value
A5: 1 | B5: AQUANATE | C5: 0.99 | E5: =D5*C5 -> 0 | G5: =F5*A5 -> 0 | I5: =H5*C5 -> 0 | K5: =J5*C5 -> 0 | M5: =L5*C5 -> 0 | O5: =N5*C5 -> 0 | Q5: =P5*C5 -> 0 | S5: =R5*C5 -> 0 | T5: =D5+F5+H5+J5+L5+N5+P5+R5 -> 0 | U5: =T5*C5 -> 0
A6: 2 | B6: BACTOXIME SYRP | C6: 2.29 | E6: =D6*C6 -> 0 | G6: =F6*A6 -> 0 | I6: =H6*C6 -> 0 | K6: =J6*C6 -> 0 | M6: =L6*C6 -> 0 | O6: =N6*C6 -> 0 | Q6: =P6*C6 -> 0 | S6: =R6*C6 -> 0 | T6: =D6+F6+H6+J6+L6+N6+P6+R6 -> 0 | U6: =T6*C6 -> 0
A7: 3 | B7: BACTOXIME 200 | C7: 3.66 | E7: =D7*C7 -> 0 | G7: =F7*A7 -> 0 | I7: =H7*C7 -> 0 | K7: =J7*C7 -> 0 | M7: =L7*C7 -> 0 | O7: =N7*C7 -> 0 | Q7: =P7*C7 -> 0 | S7: =R7*C7 -> 0 | T7: =D7+F7+H7+J7+L7+N7+P7+R7 -> 0 | U7: =T7*C7 -> 0
A8: 4 | B8: ESOPRA 20 | C8: 2.81 | E8: =D8*C8 -> 0 | G8: =F8*A8 -> 0 | I8: =H8*C8 -> 0 | K8: =J8*C8 -> 0 | M8: =L8*C8 -> 0 | O8: =N8*C8 -> 0 | Q8: =P8*C8 -> 0 | S8: =R8*C8 -> 0 | T8: =D8+F8+H8+J8+L8+N8+P8+R8 -> 0 | U8: =T8*C8 -> 0
A9: 5 | B9: ESOPRA 40 | C9: 3.46 | E9: =D9*C9 -> 0 | G9: =F9*A9 -> 0 | I9: =H9*C9 -> 0 | K9: =J9*C9 -> 0 | M9: =L9*C9 -> 0 | O9: =N9*C9 -> 0 | Q9: =P9*C9 -> 0 | S9: =R9*C9 -> 0 | T9: =D9+F9+H9+J9+L9+N9+P9+R9 -> 0 | U9: =T9*C9 -> 0
A10: 6 | B10: METAREN | C10: 1.06 | E10: =D10*C10 -> 0 | G10: =F10*A10 -> 0 | I10: =H10*C10 -> 0 | K10: =J10*C10 -> 0 | M10: =L10*C10 -> 0 | O10: =N10*C10 -> 0 | Q10: =P10*C10 -> 0 | S10: =R10*C10 -> 0 | T10: =D10+F10+H10+J10+L10+N10+P10+R10 -> 0 | U10: =T10*C10 -> 0
A11: 7 | B11: DIP3 | C11: 3.63 | E11: =D11*C11 -> 0 | G11: =F11*A11 -> 0 | I11: =H11*C11 -> 0 | K11: =J11*C11 -> 0 | M11: =L11*C11 -> 0 | O11: =N11*C11 -> 0 | Q11: =P11*C11 -> 0 | S11: =R11*C11 -> 0 | T11: =D11+F11+H11+J11+L11+N11+P11+R11 -> 0 | U11: =T11*C11 -> 0
A12: 8 | B12: PALUCURE 20/120 | C12: 0.85 | E12: =D12*C12 -> 0 | G12: =F12*A12 -> 0 | I12: =H12*C12 -> 0 | K12: =J12*C12 -> 0 | M12: =L12*C12 -> 0 | O12: =N12*C12 -> 0 | Q12: =P12*C12 -> 0 | S12: =R12*C12 -> 0 | T12: =D12+F12+H12+J12+L12+N12+P12+R12 -> 0 | U12: =T12*C12 -> 0
A13: 9 | B13: PALUCURE 80/480 | C13: 1.98 | E13: =D13*C13 -> 0 | G13: =F13*A13 -> 0 | I13: =H13*C13 -> 0 | K13: =J13*C13 -> 0 | M13: =L13*C13 -> 0 | O13: =N13*C13 -> 0 | Q13: =P13*C13 -> 0 | S13: =R13*C13 -> 0 | T13: =D13+F13+H13+J13+L13+N13+P13+R13 -> 0 | U13: =T13*C13 -> 0
A14: 10 | B14: PALUCURE 40/240 | C14: 1.98 | E14: =D14*C14 -> 0 | G14: =F14*A14 -> 0 | I14: =H14*C14 -> 0 | K14: =J14*C14 -> 0 | M14: =L14*C14 -> 0 | O14: =N14*C14 -> 0 | Q14: =P14*C14 -> 0 | S14: =R14*C14 -> 0 | T14: =D14+F14+H14+J14+L14+N14+P14+R14 -> 0 | U14: =T14*C14 -> 0
A15: 11 | B15: TRACLAV1125 | C15: 4.69 | E15: =D15*C15 -> 0 | G15: =F15*A15 -> 0 | I15: =H15*C15 -> 0 | K15: =J15*C15 -> 0 | M15: =L15*C15 -> 0 | O15: =N15*C15 -> 0 | Q15: =P15*C15 -> 0 | S15: =R15*C15 -> 0 | T15: =D15+F15+H15+J15+L15+N15+P15+R15 -> 0 | U15: =T15*C15 -> 0
A16: 12 | B16: TRACLAV 625 | C16: 2.9 | E16: =D16*C16 -> 0 | G16: =F16*A16 -> 0 | I16: =H16*C16 -> 0 | K16: =J16*C16 -> 0 | M16: =L16*C16 -> 0 | O16: =N16*C16 -> 0 | Q16: =P16*C16 -> 0 | S16: =R16*C16 -> 0 | T16: =D16+F16+H16+J16+L16+N16+P16+R16 -> 0 | U16: =T16*C16 -> 0
A17: 13 | B17: TRIAF- S | C17: 1.9 | E17: =D17*C17 -> 0 | G17: =F17*C17 -> 0 | I17: =H17*C17 -> 0 | K17: =J17*C17 -> 0 | M17: =L17*C17 -> 0 | O17: =N17*C17 -> 0 | Q17: =P17*C17 -> 0 | S17: =R17*C17 -> 0 | T17: =D17+F17+H17+J17+L17+N17+P17+R17 -> 0 | U17: =T17*C17 -> 0
A18: 14 | B18: PALUCURE PLUS 80/480 | C18: 2.4 | E18: =D18*C18 -> 0 | G18: =F18*C18 -> 0 | I18: =H18*C18 -> 0 | K18: =J18*C18 -> 0 | M18: =L18*C18 -> 0 | O18: =N18*C18 -> 0 | Q18: =P18*C18 -> 0 | S18: =R18*C18 -> 0 | T18: =D18+F18+H18+J18+L18+N18+P18+R18 -> 0 | U18: =T18*C18 -> 0
A19: 15 | B19: TRACLAV 1.2 | C19: 1.5 | E19: =D19*C19 -> 0 | G19: =F19*A19 -> 0 | I19: =H19*C19 -> 0 | K19: =J19*C19 -> 0 | M19: =L19*C19 -> 0 | O19: =N19*C19 -> 0 | Q19: =P19*C19 -> 0 | S19: =R19*C19 -> 0 | T19: =D19+F19+H19+J19+L19+N19+P19+R19 -> 0 | U19: =T19*C19 -> 0
A20: 16 | B20: TRACLAV1125 SACHT | C20: 5.38 | D20: 0 | E20: =D20*C20 -> 0 | G20: =F20*C20 -> 0 | H20: 0 | I20: =H20*C20 -> 0 | K20: =J20*C20 -> 0 | L20: 0 | M20: =L20*C20 -> 0 | N20: 0 | O20: =N20*C20 -> 0 | Q20: =P20*C20 -> 0 | R20: 0 | S20: =R20*C20 -> 0 | T20: =D20+F20+H20+J20+L20+N20+P20+R20 -> 0 | U20: =T20*C20 -> 0
A21: 17 | B21: TUMI | C21: 2 | D21: 0 | E21: =D21*C21 -> 0 | G21: =F21*A21 -> 0 | H21: 0 | I21: =H21*C21 -> 0 | K21: =J21*C21 -> 0 | L21: 0 | M21: =L21*C21 -> 0 | N21: 0 | O21: =N21*C21 -> 0 | Q21: =P21*C21 -> 0 | R21: 0 | S21: =R21*C21 -> 0 | T21: =D21+F21+H21+J21+L21+N21+P21+R21 -> 0 | U21: =T21*C21 -> 0
B22: TOTAL | E22: =SUM(E5:E19) -> 0 | G22: =SUM(G5:G19) -> 0 | I22: =SUM(I5:I19) -> 0 | K22: =SUM(K5:K19) -> 0 | M22: =SUM(M5:M19) -> 0 | O22: =SUM(O5:O19) -> 0 | Q22: =SUM(Q5:Q19) -> 0 | S22: =SUM(S5:S19) -> 0 | U22: =SUM(E22+I22+M22+O22+Q22+S22) -> 0

Sheet BAMAKO POOL-CAMED &TEDIS&AFRICA
A2: MONTH | B2: 45962
D3: COMMUNE 1 | F3: COMMUNE 2 | H3: COMMUNE 3 | J3: COMMUNE 4 | L3: COMMUNE 5 | N3: COMMUNE 6 | P3: KOULIKORO | R3: KATI | T3: TOTAL
B4: PRODUCT NAME | C4: CIF | D4: Unit | E4: value | F4: Unit | G4: Value | H4: Unit | I4: Value | J4: Unit | K4: Value | L4: Unit | M4: Value | N4: Unit | O4: Value | P4: Unit | Q4: Value | R4: Unit | S4: Value | T4: Unit | U4: Value
A5: 1 | B5: AQUANATE | C5: 0.99 | D5: 620 | E5: =D5*C5 -> 613.8 | G5: =F5*A5 -> 0 | H5: 0 | I5: =H5*C5 -> 0 | K5: 0 | L5: 0 | M5: =L5*C5 -> 0 | N5: 490 | O5: =N5*C5 -> 485.1 | Q5: =P5*C5 -> 0 | R5: 480 | S5: =R5*C5 -> 475.2 | T5: =D5+F5+H5+J5+L5+N5+P5+R5 -> 1590 | U5: =T5*C5 -> 1574.1
A6: 2 | B6: BACTOXIME SYRP | C6: 2.29 | D6: 100 | E6: =D6*C6 -> 229 | G6: =F6*A6 -> 0 | H6: 0 | I6: =H6*C6 -> 0 | J6: 0 | K6: =J6*C6 -> 0 | L6: 0 | M6: =L6*C6 -> 0 | N6: 0 | O6: =N6*C6 -> 0 | Q6: =P6*C6 -> 0 | R6: 0 | S6: =R6*C6 -> 0 | T6: =D6+F6+H6+J6+L6+N6+P6+R6 -> 100 | U6: =T6*C6 -> 229
A7: 3 | B7: BACTOXIME 200 | C7: 3.66 | D7: 9 | E7: =D7*C7 -> 32.94 | G7: =F7*A7 -> 0 | H7: 0 | I7: =H7*C7 -> 0 | K7: 0 | L7: 12 | M7: =L7*C7 -> 43.92 | N7: 16 | O7: =N7*C7 -> 58.56 | Q7: =P7*C7 -> 0 | R7: 10 | S7: =R7*C7 -> 36.6 | T7: =D7+F7+H7+J7+L7+N7+P7+R7 -> 47 | U7: =T7*C7 -> 172.02
A8: 4 | B8: ESOPRA 20 | C8: 2.81 | D8: 0 | E8: =D8*C8 -> 0 | G8: =F8*A8 -> 0 | H8: 0 | I8: =H8*C8 -> 0 | K8: =J8*C8 -> 0 | L8: 0 | M8: =L8*C8 -> 0 | N8: 0 | O8: =N8*C8 -> 0 | Q8: =P8*C8 -> 0 | R8: 0 | S8: =R8*C8 -> 0 | T8: =D8+F8+H8+J8+L8+N8+P8+R8 -> 0 | U8: =T8*C8 -> 0
A9: 5 | B9: ESOPRA 40 | C9: 3.46 | D9: 0 | E9: =D9*C9 -> 0 | G9: 0 | H9: 0 | I9: =H9*C9 -> 0 | K9: =J9*C9 -> 0 | L9: 6 | M9: =L9*C9 -> 20.76 | N9: 5 | O9: =N9*C9 -> 17.3 | Q9: =P9*C9 -> 0 | R9: 0 | S9: =R9*C9 -> 0 | T9: =D9+F9+H9+J9+L9+N9+P9+R9 -> 11 | U9: =T9*C9 -> 38.06
A10: 6 | B10: METAREN | C10: 1.06 | D10: 0 | E10: =D10*C10 -> 0 | G10: =F10*A10 -> 0 | H10: 0 | I10: =H10*C10 -> 0 | K10: 0 | L10: 0 | M10: =L10*C10 -> 0 | N10: 0 | O10: =N10*C10 -> 0 | Q10: =P10*C10 -> 0 | R10: 0 | S10: =R10*C10 -> 0 | T10: =D10+F10+H10+J10+L10+N10+P10+R10 -> 0 | U10: =T10*C10 -> 0
A11: 7 | B11: DIP3 | C11: 3.63 | D11: 0 | E11: =D11*C11 -> 0 | G11: =F11*A11 -> 0 | H11: 0 | I11: =H11*C11 -> 0 | K11: =J11*C11 -> 0 | L11: 0 | M11: =L11*C11 -> 0 | N11: 0 | O11: =N11*C11 -> 0 | Q11: =P11*C11 -> 0 | R11: 0 | S11: =R11*C11 -> 0 | T11: =D11+F11+H11+J11+L11+N11+P11+R11 -> 0 | U11: =T11*C11 -> 0
A12: 8 | B12: PALUCURE 20/120 | C12: 0.85 | D12: 0 | E12: =D12*C12 -> 0 | G12: =F12*A12 -> 0 | H12: 0 | I12: =H12*C12 -> 0 | K12: =J12*C12 -> 0 | L12: 0 | M12: =L12*C12 -> 0 | N12: 0 | O12: =N12*C12 -> 0 | Q12: =P12*C12 -> 0 | R12: 0 | S12: =R12*C12 -> 0 | T12: =D12+F12+H12+J12+L12+N12+P12+R12 -> 0 | U12: =T12*C12 -> 0
A13: 9 | B13: PALUCURE 80/480 | C13: 1.98 | D13: 0 | E13: =D13*C13 -> 0 | G13: =F13*A13 -> 0 | H13: 0 | I13: =H13*C13 -> 0 | K13: =J13*C13 -> 0 | L13: 0 | M13: =L13*C13 -> 0 | N13: 0 | O13: =N13*C13 -> 0 | Q13: =P13*C13 -> 0 | R13: 0 | S13: =R13*C13 -> 0 | T13: =D13+F13+H13+J13+L13+N13+P13+R13 -> 0 | U13: =T13*C13 -> 0
A14: 10 | B14: PALUCURE 40/240 | C14: 1.98 | D14: 0 | E14: =D14*C14 -> 0 | G14: =F14*A14 -> 0 | H14: 0 | I14: =H14*C14 -> 0 | K14: =J14*C14 -> 0 | L14: 0 | M14: =L14*C14 -> 0 | N14: 0 | O14: =N14*C14 -> 0 | Q14: =P14*C14 -> 0 | R14: 0 | S14: =R14*C14 -> 0 | T14: =D14+F14+H14+J14+L14+N14+P14+R14 -> 0 | U14: =T14*C14 -> 0
A15: 11 | B15: TRACLAV1125 | C15: 4.69 | D15: 0 | E15: =D15*C15 -> 0 | G15: =F15*A15 -> 0 | H15: 0 | I15: =H15*C15 -> 0 | K15: =J15*C15 -> 0 | L15: 0 | M15: =L15*C15 -> 0 | N15: 0 | O15: =N15*C15 -> 0 | Q15: =P15*C15 -> 0 | R15: 0 | S15: =R15*C15 -> 0 | T15: =D15+F15+H15+J15+L15+N15+P15+R15 -> 0 | U15: =T15*C15 -> 0
A16: 12 | B16: TRACLAV 625 | C16: 2.9 | D16: 0 | E16: =D16*C16 -> 0 | G16: =F16*A16 -> 0 | H16: 0 | I16: =H16*C16 -> 0 | K16: =J16*C16 -> 0 | L16: 0 | M16: =L16*C16 -> 0 | N16: 0 | O16: =N16*C16 -> 0 | Q16: =P16*C16 -> 0 | R16: 0 | S16: =R16*C16 -> 0 | T16: =D16+F16+H16+J16+L16+N16+P16+R16 -> 0 | U16: =T16*C16 -> 0
A17: 13 | B17: TRIAF- S | C17: 1.9 | D17: 0 | E17: =D17*C17 -> 0 | G17: =F17*C17 -> 0 | H17: 0 | I17: =H17*C17 -> 0 | K17: =J17*C17 -> 0 | L17: 0 | M17: =L17*C17 -> 0 | N17: 0 | O17: =N17*C17 -> 0 | Q17: =P17*C17 -> 0 | R17: 0 | S17: =R17*C17 -> 0 | T17: 0 | U17: =T17*C17 -> 0
A18: 14 | B18: PALUCURE PLUS 80/480 | C18: 2.4 | D18: 0 | E18: =D18*C18 -> 0 | G18: =F18*C18 -> 0 | H18: 0 | I18: =H18*C18 -> 0 | K18: =J18*C18 -> 0 | L18: 0 | M18: =L18*C18 -> 0 | N18: 0 | O18: =N18*C18 -> 0 | Q18: =P18*C18 -> 0 | R18: 0 | S18: =R18*C18 -> 0 | T18: 0 | U18: =T18*C18 -> 0
A19: 15 | B19: TRACLAV 1.2 | C19: 1.5 | D19: 0 | E19: =D19*C19 -> 0 | G19: =F19*A19 -> 0 | H19: 0 | I19: =H19*C19 -> 0 | K19: =J19*C19 -> 0 | L19: 0 | M19: =L19*C19 -> 0 | N19: 0 | O19: =N19*C19 -> 0 | Q19: =P19*C19 -> 0 | R19: 0 | S19: =R19*C19 -> 0 | T19: =D19+F19+H19+J19+L19+N19+P19+R19 -> 0 | U19: =T19*C19 -> 0
A20: 16 | B20: TRACLAV1125 SACHT | C20: 5.38 | D20: 0 | E20: =D20*C20 -> 0 | G20: =F20*C20 -> 0 | H20: 0 | I20: =H20*C20 -> 0 | K20: =J20*C20 -> 0 | L20: 0 | M20: =L20*C20 -> 0 | N20: 0 | O20: =N20*C20 -> 0 | Q20: =P20*C20 -> 0 | R20: 0 | S20: =R20*C20 -> 0 | T20: =D20+F20+H20+J20+L20+N20+P20+R20 -> 0 | U20: =T20*C20 -> 0
A21: 17 | B21: TUMI | C21: 2 | D21: 0 | E21: =D21*C21 -> 0 | G21: =F21*A21 -> 0 | H21: 0 | I21: =H21*C21 -> 0 | K21: =J21*C21 -> 0 | L21: 0 | M21: =L21*C21 -> 0 | N21: 0 | O21: =N21*C21 -> 0 | Q21: =P21*C21 -> 0 | R21: 0 | S21: =R21*C21 -> 0 | T21: =D21+F21+H21+J21+L21+N21+P21+R21 -> 0 | U21: =T21*C21 -> 0
B22: TOTAL | E22: =SUM(E5:E21) -> 875.74 | G22: =SUM(G5:G19) -> 0 | I22: =SUM(I5:I21) -> 0 | K22: =SUM(K5:K19) -> 0 | M22: =SUM(M5:M21) -> 64.68 | O22: =SUM(O5:O21) -> 560.96 | Q22: =SUM(Q5:Q19) -> 0 | S22: =SUM(S5:S21) -> 511.8 | U22: =SUM(U5:U21) -> 2013.18

Sheet BAMAKO POOL-TOTAL
A2: MONTH | B2: 45597
D3: COMMUNE 1 | F3: COMMUNE 2 | H3: COMMUNE 3 | J3: COMMUNE 4 | L3: COMMUNE 5 | N3: COMMUNE 6 | P3: KATI | R3: TOTAL | T3: BAMAKO/4 | V3: BAMAKO/4
B4: PRODUCT NAME | C4: CIF | D4: Unit | E4: value | F4: Unit | G4: Value | H4: Unit | I4: Value | J4: Unit | K4: Value | L4: Unit | M4: Value | N4: Unit | O4: Value | P4: Unit | Q4: Value | R4: Unit | S4: Value | T4: Unit | U4: Value
A5: 1 | B5: AQUANATE | C5: 0.99 | D5: ='BAMAKO POOL-LABOREX'!D5+'BAMAKO POOL-UBIPHARM'!D5+'BAMAKO POOL-AFRICALA'!D5+'BAMAKO POOL-CAMED &TEDIS&AFRICA'!D5 -> 774 | E5: =D5*C5 -> 766.26 | F5: ='BAMAKO POOL-LABOREX'!F5+'BAMAKO POOL-UBIPHARM'!F5+'BAMAKO POOL-AFRICALA'!F5+'BAMAKO POOL-CAMED &TEDIS&AFRICA'!F5 -> 114 | G5: =F5*C5 -> 112.86 | H5: ='BAMAKO POOL-LABOREX'!H5+'BAMAKO POOL-UBIPHARM'!H5+'BAMAKO POOL-AFRICALA'!H5+'BAMAKO POOL-CAMED &TEDIS&AFRICA'!H5 -> 833 | I5: =H5*C5 -> 824.67 | J5: ='BAMAKO POOL-LABOREX'!J5+'BAMAKO POOL-UBIPHARM'!J5+'BAMAKO POOL-AFRICALA'!J5+'BAMAKO POOL-CAMED &TEDIS&AFRICA'!J5 -> 317 | K5: =J5*C5 -> 313.83 | L5: ='BAMAKO POOL-LABOREX'!L5+'BAMAKO POOL-UBIPHARM'!L5+'BAMAKO POOL-AFRICALA'!L5+'BAMAKO POOL-CAMED &TEDIS&AFRICA'!L5 -> 1633 | M5: =L5*C5 -> 1616.67 | N5: ='BAMAKO POOL-LABOREX'!N5+'BAMAKO POOL-UBIPHARM'!N5+'BAMAKO POOL-AFRICALA'!N5+'BAMAKO POOL-CAMED &TEDIS&AFRICA'!N5 -> 4452 | O5: =N5*C5 -> 4407.48 | P5: ='BAMAKO POOL-LABOREX'!R5+'BAMAKO POOL-UBIPHARM'!R5+'BAMAKO POOL-AFRICALA'!R5+'BAMAKO POOL-CAMED &TEDIS&AFRICA'!R5 -> 5001 | Q5: =P5*C5 -> 4950.99 | R5: =D5+F5+H5+J5+L5+N5++P5 -> 13124 | S5: =R5*C5 -> 12992.76 | T5: =D5+F5+H5+J5+L5+N5 -> 8123 | U5: =T5*$C5 -> 8041.77 | V5: =S5/5 -> 2598.552 | W5: =U5/4 -> 2010.4425
A6: 2 | B6: BACTOXIME SYRP | C6: 2.29 | D6: ='BAMAKO POOL-LABOREX'!D6+'BAMAKO POOL-UBIPHARM'!D6+'BAMAKO POOL-AFRICALA'!D6+'BAMAKO POOL-CAMED &TEDIS&AFRICA'!D6 -> 188 | E6: =D6*C6 -> 430.52 | F6: ='BAMAKO POOL-LABOREX'!F6+'BAMAKO POOL-UBIPHARM'!F6+'BAMAKO POOL-AFRICALA'!F6+'BAMAKO POOL-CAMED &TEDIS&AFRICA'!F6 -> 70 | G6: =F6*C6 -> 160.3 | H6: ='BAMAKO POOL-LABOREX'!H6+'BAMAKO POOL-UBIPHARM'!H6+'BAMAKO POOL-AFRICALA'!H6+'BAMAKO POOL-CAMED &TEDIS&AFRICA'!H6 -> 65 | I6: =H6*C6 -> 148.85 | J6: ='BAMAKO POOL-LABOREX'!J6+'BAMAKO POOL-UBIPHARM'!J6+'BAMAKO POOL-AFRICALA'!J6+'BAMAKO POOL-CAMED &TEDIS&AFRICA'!J6 -> 58 | K6: =J6*C6 -> 132.82 | L6: ='BAMAKO POOL-LABOREX'!L6+'BAMAKO POOL-UBIPHARM'!L6+'BAMAKO POOL-AFRICALA'!L6+'BAMAKO POOL-CAMED &TEDIS&AFRICA'!L6 -> 83 | M6: =L6*C6 -> 190.07 | N6: ='BAMAKO POOL-LABOREX'!N6+'BAMAKO POOL-UBIPHARM'!N6+'BAMAKO POOL-AFRICALA'!N6+'BAMAKO POOL-CAMED &TEDIS&AFRICA'!N6 -> 168 | O6: =N6*C6 -> 384.72 | P6: ='BAMAKO POOL-LABOREX'!R6+'BAMAKO POOL-UBIPHARM'!R6+'BAMAKO POOL-AFRICALA'!R6+'BAMAKO POOL-CAMED &TEDIS&AFRICA'!R6 -> 32 | Q6: =P6*C6 -> 73.28 | R6: =D6+F6+H6+J6+L6+N6++P6 -> 664 | S6: =R6*C6 -> 1520.56 | T6: =D6+F6+H6+J6+L6+N6 -> 632 | U6: =T6*$C6 -> 1447.28 | V6: =S6/5 -> 304.112 | W6: =U6/4 -> 361.82
A7: 3 | B7: BACTOXIME 200 | C7: 3.66 | D7: ='BAMAKO POOL-LABOREX'!D7+'BAMAKO POOL-UBIPHARM'!D7+'BAMAKO POOL-AFRICALA'!D7+'BAMAKO POOL-CAMED &TEDIS&AFRICA'!D7 -> 82 | E7: =D7*C7 -> 300.12 | F7: ='BAMAKO POOL-LABOREX'!F7+'BAMAKO POOL-UBIPHARM'!F7+'BAMAKO POOL-AFRICALA'!F7+'BAMAKO POOL-CAMED &TEDIS&AFRICA'!F7 -> 8 | G7: =F7*C7 -> 29.28 | H7: ='BAMAKO POOL-LABOREX'!H7+'BAMAKO POOL-UBIPHARM'!H7+'BAMAKO POOL-AFRICALA'!H7+'BAMAKO POOL-CAMED &TEDIS&AFRICA'!H7 -> 88 | I7: =H7*C7 -> 322.08 | J7: ='BAMAKO POOL-LABOREX'!J7+'BAMAKO POOL-UBIPHARM'!J7+'BAMAKO POOL-AFRICALA'!J7+'BAMAKO POOL-CAMED &TEDIS&AFRICA'!J7 -> 8 | K7: =J7*C7 -> 29.28 | L7: ='BAMAKO POOL-LABOREX'!L7+'BAMAKO POOL-UBIPHARM'!L7+'BAMAKO POOL-AFRICALA'!L7+'BAMAKO POOL-CAMED &TEDIS&AFRICA'!L7 -> 160 | M7: =L7*C7 -> 585.6 | N7: ='BAMAKO POOL-LABOREX'!N7+'BAMAKO POOL-UBIPHARM'!N7+'BAMAKO POOL-AFRICALA'!N7+'BAMAKO POOL-CAMED &TEDIS&AFRICA'!N7 -> 177 | O7: =N7*C7 -> 647.82 | P7: ='BAMAKO POOL-LABOREX'!R7+'BAMAKO POOL-UBIPHARM'!R7+'BAMAKO POOL-AFRICALA'!R7+'BAMAKO POOL-CAMED &TEDIS&AFRICA'!R7 -> 114 | Q7: =P7*C7 -> 417.24 | R7: =D7+F7+H7+J7+L7+N7++P7 -> 637 | S7: =R7*C7 -> 2331.42 | T7: =D7+F7+H7+J7+L7+N7 -> 523 | U7: =T7*$C7 -> 1914.18 | V7: =S7/5 -> 466.284 | W7: =U7/4 -> 478.545
A8: 4 | B8: ESOPRA 20 | C8: 2.81 | D8: ='BAMAKO POOL-LABOREX'!D8+'BAMAKO POOL-UBIPHARM'!D8+'BAMAKO POOL-AFRICALA'!D8+'BAMAKO POOL-CAMED &TEDIS&AFRICA'!D8 -> 38 | E8: =D8*C8 -> 106.78 | F8: ='BAMAKO POOL-LABOREX'!F8+'BAMAKO POOL-UBIPHARM'!F8+'BAMAKO POOL-AFRICALA'!F8+'BAMAKO POOL-CAMED &TEDIS&AFRICA'!F8 -> 21 | G8: =F8*C8 -> 59.01 | H8: ='BAMAKO POOL-LABOREX'!H8+'BAMAKO POOL-UBIPHARM'!H8+'BAMAKO POOL-AFRICALA'!H8+'BAMAKO POOL-CAMED &TEDIS&AFRICA'!H8 -> 41 | I8: =H8*C8 -> 115.21 | J8: ='BAMAKO POOL-LABOREX'!J8+'BAMAKO POOL-UBIPHARM'!J8+'BAMAKO POOL-AFRICALA'!J8+'BAMAKO POOL-CAMED &TEDIS&AFRICA'!J8 -> 25 | K8: =J8*C8 -> 70.25 | L8: ='BAMAKO POOL-LABOREX'!L8+'BAMAKO POOL-UBIPHARM'!L8+'BAMAKO POOL-AFRICALA'!L8+'BAMAKO POOL-CAMED &TEDIS&AFRICA'!L8 -> 19 | M8: =L8*C8 -> 53.39 | N8: ='BAMAKO POOL-LABOREX'!N8+'BAMAKO POOL-UBIPHARM'!N8+'BAMAKO POOL-AFRICALA'!N8+'BAMAKO POOL-CAMED &TEDIS&AFRICA'!N8 -> 25 | O8: =N8*C8 -> 70.25 | P8: ='BAMAKO POOL-LABOREX'!R8+'BAMAKO POOL-UBIPHARM'!R8+'BAMAKO POOL-AFRICALA'!R8+'BAMAKO POOL-CAMED &TEDIS&AFRICA'!R8 -> 32 | Q8: =P8*C8 -> 89.92 | R8: =D8+F8+H8+J8+L8+N8++P8 -> 201 | S8: =R8*C8 -> 564.81 | T8: =D8+F8+H8+J8+L8+N8 -> 169 | U8: =T8*$C8 -> 474.89 | V8: =S8/5 -> 112.962 | W8: =U8/4 -> 118.7225
A9: 5 | B9: ESOPRA 40 | C9: 3.46 | D9: ='BAMAKO POOL-LABOREX'!D9+'BAMAKO POOL-UBIPHARM'!D9+'BAMAKO POOL-AFRICALA'!D9+'BAMAKO POOL-CAMED &TEDIS&AFRICA'!D9 -> 43 | E9: =D9*C9 -> 148.78 | F9: ='BAMAKO POOL-LABOREX'!F9+'BAMAKO POOL-UBIPHARM'!F9+'BAMAKO POOL-AFRICALA'!F9+'BAMAKO POOL-CAMED &TEDIS&AFRICA'!F9 -> 35 | G9: =F9*C9 -> 121.1 | H9: ='BAMAKO POOL-LABOREX'!H9+'BAMAKO POOL-UBIPHARM'!H9+'BAMAKO POOL-AFRICALA'!H9+'BAMAKO POOL-CAMED &TEDIS&AFRICA'!H9 -> 57 | I9: =H9*C9 -> 197.22 | J9: ='BAMAKO POOL-LABOREX'!J9+'BAMAKO POOL-UBIPHARM'!J9+'BAMAKO POOL-AFRICALA'!J9+'BAMAKO POOL-CAMED &TEDIS&AFRICA'!J9 -> 36 | K9: =J9*C9 -> 124.56 | L9: ='BAMAKO POOL-LABOREX'!L9+'BAMAKO POOL-UBIPHARM'!L9+'BAMAKO POOL-AFRICALA'!L9+'BAMAKO POOL-CAMED &TEDIS&AFRICA'!L9 -> 80 | M9: =L9*C9 -> 276.8 | N9: ='BAMAKO POOL-LABOREX'!N9+'BAMAKO POOL-UBIPHARM'!N9+'BAMAKO POOL-AFRICALA'!N9+'BAMAKO POOL-CAMED &TEDIS&AFRICA'!N9 -> 97 | O9: =N9*C9 -> 335.62 | P9: ='BAMAKO POOL-LABOREX'!R9+'BAMAKO POOL-UBIPHARM'!R9+'BAMAKO POOL-AFRICALA'!R9+'BAMAKO POOL-CAMED &TEDIS&AFRICA'!R9 -> 75 | Q9: =P9*C9 -> 259.5 | R9: =D9+F9+H9+J9+L9+N9++P9 -> 423 | S9: =R9*C9 -> 1463.58 | T9: =D9+F9+H9+J9+L9+N9 -> 348 | U9: =T9*$C9 -> 1204.08 | V9: =S9/5 -> 292.716 | W9: =U9/4 -> 301.02
A10: 6 | B10: METAREN | C10: 1.06 | D10: ='BAMAKO POOL-LABOREX'!D10+'BAMAKO POOL-UBIPHARM'!D10+'BAMAKO POOL-AFRICALA'!D10+'BAMAKO POOL-CAMED &TEDIS&AFRICA'!D10 -> 0 | E10: =D10*C10 -> 0 | F10: ='BAMAKO POOL-LABOREX'!F10+'BAMAKO POOL-UBIPHARM'!F10+'BAMAKO POOL-AFRICALA'!F10+'BAMAKO POOL-CAMED &TEDIS&AFRICA'!F10 -> 0 | G10: =F10*C10 -> 0 | H10: ='BAMAKO POOL-LABOREX'!H10+'BAMAKO POOL-UBIPHARM'!H10+'BAMAKO POOL-AFRICALA'!H10+'BAMAKO POOL-CAMED &TEDIS&AFRICA'!H10 -> 0 | I10: =H10*C10 -> 0 | J10: ='BAMAKO POOL-LABOREX'!J10+'BAMAKO POOL-UBIPHARM'!J10+'BAMAKO POOL-AFRICALA'!J10+'BAMAKO POOL-CAMED &TEDIS&AFRICA'!J10 -> 0 | K10: =J10*C10 -> 0 | L10: ='BAMAKO POOL-LABOREX'!L10+'BAMAKO POOL-UBIPHARM'!L10+'BAMAKO POOL-AFRICALA'!L10+'BAMAKO POOL-CAMED &TEDIS&AFRICA'!L10 -> 0 | M10: =L10*C10 -> 0 | N10: ='BAMAKO POOL-LABOREX'!N10+'BAMAKO POOL-UBIPHARM'!N10+'BAMAKO POOL-AFRICALA'!N10+'BAMAKO POOL-CAMED &TEDIS&AFRICA'!N10 -> 0 | O10: =N10*C10 -> 0 | P10: ='BAMAKO POOL-LABOREX'!R10+'BAMAKO POOL-UBIPHARM'!R10+'BAMAKO POOL-AFRICALA'!R10+'BAMAKO POOL-CAMED &TEDIS&AFRICA'!R10 -> 0 | Q10: =P10*C10 -> 0 | R10: =D10+F10+H10+J10+L10+N10++P10 -> 0 | S10: =R10*C10 -> 0 | T10: =D10+F10+H10+J10+L10+N10 -> 0 | U10: =T10*$C10 -> 0 | V10: =S10/5 -> 0 | W10: =U10/4 -> 0
A11: 7 | B11: DIP3 | C11: 3.63 | D11: ='BAMAKO POOL-LABOREX'!D11+'BAMAKO POOL-UBIPHARM'!D11+'BAMAKO POOL-AFRICALA'!D11+'BAMAKO POOL-CAMED &TEDIS&AFRICA'!D11 -> 0 | E11: =D11*C11 -> 0 | F11: ='BAMAKO POOL-LABOREX'!F11+'BAMAKO POOL-UBIPHARM'!F11+'BAMAKO POOL-AFRICALA'!F11+'BAMAKO POOL-CAMED &TEDIS&AFRICA'!F11 -> 0 | G11: =F11*C11 -> 0 | H11: ='BAMAKO POOL-LABOREX'!H11+'BAMAKO POOL-UBIPHARM'!H11+'BAMAKO POOL-AFRICALA'!H11+'BAMAKO POOL-CAMED &TEDIS&AFRICA'!H11 -> 0 | I11: =H11*C11 -> 0 | J11: ='BAMAKO POOL-LABOREX'!J11+'BAMAKO POOL-UBIPHARM'!J11+'BAMAKO POOL-AFRICALA'!J11+'BAMAKO POOL-CAMED &TEDIS&AFRICA'!J11 -> 0 | K11: =J11*C11 -> 0 | L11: ='BAMAKO POOL-LABOREX'!L11+'BAMAKO POOL-UBIPHARM'!L11+'BAMAKO POOL-AFRICALA'!L11+'BAMAKO POOL-CAMED &TEDIS&AFRICA'!L11 -> 0 | M11: =L11*C11 -> 0 | N11: ='BAMAKO POOL-LABOREX'!N11+'BAMAKO POOL-UBIPHARM'!N11+'BAMAKO POOL-AFRICALA'!N11+'BAMAKO POOL-CAMED &TEDIS&AFRICA'!N11 -> 0 | O11: =N11*C11 -> 0 | P11: ='BAMAKO POOL-LABOREX'!R11+'BAMAKO POOL-UBIPHARM'!R11+'BAMAKO POOL-AFRICALA'!R11+'BAMAKO POOL-CAMED &TEDIS&AFRICA'!R11 -> 0 | Q11: =P11*C11 -> 0 | R11: =D11+F11+H11+J11+L11+N11++P11 -> 0 | S11: =R11*C11 -> 0 | T11: =D11+F11+H11+J11+L11+N11 -> 0 | U11: =T11*$C11 -> 0 | V11: =S11/5 -> 0 | W11: =U11/4 -> 0
A12: 8 | B12: PALUCURE 20/120 | C12: 0.85 | D12: ='BAMAKO POOL-LABOREX'!D12+'BAMAKO POOL-UBIPHARM'!D12+'BAMAKO POOL-AFRICALA'!D12+'BAMAKO POOL-CAMED &TEDIS&AFRICA'!D12 -> 9 | E12: =D12*C12 -> 7.65 | F12: ='BAMAKO POOL-LABOREX'!F12+'BAMAKO POOL-UBIPHARM'!F12+'BAMAKO POOL-AFRICALA'!F12+'BAMAKO POOL-CAMED &TEDIS&AFRICA'!F12 -> 0 | G12: =F12*C12 -> 0 | H12: ='BAMAKO POOL-LABOREX'!H12+'BAMAKO POOL-UBIPHARM'!H12+'BAMAKO POOL-AFRICALA'!H12+'BAMAKO POOL-CAMED &TEDIS&AFRICA'!H12 -> 55 | I12: =H12*C12 -> 46.75 | J12: ='BAMAKO POOL-LABOREX'!J12+'BAMAKO POOL-UBIPHARM'!J12+'BAMAKO POOL-AFRICALA'!J12+'BAMAKO POOL-CAMED &TEDIS&AFRICA'!J12 -> 0 | K12: =J12*C12 -> 0 | L12: ='BAMAKO POOL-LABOREX'!L12+'BAMAKO POOL-UBIPHARM'!L12+'BAMAKO POOL-AFRICALA'!L12+'BAMAKO POOL-CAMED &TEDIS&AFRICA'!L12 -> 22 | M12: =L12*C12 -> 18.7 | N12: ='BAMAKO POOL-LABOREX'!N12+'BAMAKO POOL-UBIPHARM'!N12+'BAMAKO POOL-AFRICALA'!N12+'BAMAKO POOL-CAMED &TEDIS&AFRICA'!N12 -> 100 | O12: =N12*C12 -> 85 | P12: ='BAMAKO POOL-LABOREX'!R12+'BAMAKO POOL-UBIPHARM'!R12+'BAMAKO POOL-AFRICALA'!R12+'BAMAKO POOL-CAMED &TEDIS&AFRICA'!R12 -> 35 | Q12: =P12*C12 -> 29.75 | R12: =D12+F12+H12+J12+L12+N12++P12 -> 221 | S12: =R12*C12 -> 187.85 | T12: =D12+F12+H12+J12+L12+N12 -> 186 | U12: =T12*$C12 -> 158.1 | V12: =S12/5 -> 37.57 | W12: =U12/4 -> 39.525
A13: 9 | B13: PALUCURE 80/480 | C13: 1.98 | D13: ='BAMAKO POOL-LABOREX'!D13+'BAMAKO POOL-UBIPHARM'!D13+'BAMAKO POOL-AFRICALA'!D13+'BAMAKO POOL-CAMED &TEDIS&AFRICA'!D13 -> 108 | E13: =D13*C13 -> 213.84 | F13: ='BAMAKO POOL-LABOREX'!F13+'BAMAKO POOL-UBIPHARM'!F13+'BAMAKO POOL-AFRICALA'!F13+'BAMAKO POOL-CAMED &TEDIS&AFRICA'!F13 -> 79 | G13: =F13*C13 -> 156.42 | H13: ='BAMAKO POOL-LABOREX'!H13+'BAMAKO POOL-UBIPHARM'!H13+'BAMAKO POOL-AFRICALA'!H13+'BAMAKO POOL-CAMED &TEDIS&AFRICA'!H13 -> 229 | I13: =H13*C13 -> 453.42 | J13: ='BAMAKO POOL-LABOREX'!J13+'BAMAKO POOL-UBIPHARM'!J13+'BAMAKO POOL-AFRICALA'!J13+'BAMAKO POOL-CAMED &TEDIS&AFRICA'!J13 -> 79 | K13: =J13*C13 -> 156.42 | L13: ='BAMAKO POOL-LABOREX'!L13+'BAMAKO POOL-UBIPHARM'!L13+'BAMAKO POOL-AFRICALA'!L13+'BAMAKO POOL-CAMED &TEDIS&AFRICA'!L13 -> 223 | M13: =L13*C13 -> 441.54 | N13: ='BAMAKO POOL-LABOREX'!N13+'BAMAKO POOL-UBIPHARM'!N13+'BAMAKO POOL-AFRICALA'!N13+'BAMAKO POOL-CAMED &TEDIS&AFRICA'!N13 -> 380 | O13: =N13*C13 -> 752.4 | P13: ='BAMAKO POOL-LABOREX'!R13+'BAMAKO POOL-UBIPHARM'!R13+'BAMAKO POOL-AFRICALA'!R13+'BAMAKO POOL-CAMED &TEDIS&AFRICA'!R13 -> 353 | Q13: =P13*C13 -> 698.94 | R13: =D13+F13+H13+J13+L13+N13++P13 -> 1451 | S13: =R13*C13 -> 2872.98 | T13: =D13+F13+H13+J13+L13+N13 -> 1098 | U13: =T13*$C13 -> 2174.04 | V13: =S13/5 -> 574.596 | W13: =U13/4 -> 543.51
A14: 10 | B14: PALUCURE 40/240 | C14: 1.98 | D14: ='BAMAKO POOL-LABOREX'!D14+'BAMAKO POOL-UBIPHARM'!D14+'BAMAKO POOL-AFRICALA'!D14+'BAMAKO POOL-CAMED &TEDIS&AFRICA'!D14 -> 17 | E14: =D14*C14 -> 33.66 | F14: ='BAMAKO POOL-LABOREX'!F14+'BAMAKO POOL-UBIPHARM'!F14+'BAMAKO POOL-AFRICALA'!F14+'BAMAKO POOL-CAMED &TEDIS&AFRICA'!F14 -> 7 | G14: =F14*C14 -> 13.86 | H14: ='BAMAKO POOL-LABOREX'!H14+'BAMAKO POOL-UBIPHARM'!H14+'BAMAKO POOL-AFRICALA'!H14+'BAMAKO POOL-CAMED &TEDIS&AFRICA'!H14 -> 46 | I14: =H14*C14 -> 91.08 | J14: ='BAMAKO POOL-LABOREX'!J14+'BAMAKO POOL-UBIPHARM'!J14+'BAMAKO POOL-AFRICALA'!J14+'BAMAKO POOL-CAMED &TEDIS&AFRICA'!J14 -> 8 | K14: =J14*C14 -> 15.84 | L14: ='BAMAKO POOL-LABOREX'!L14+'BAMAKO POOL-UBIPHARM'!L14+'BAMAKO POOL-AFRICALA'!L14+'BAMAKO POOL-CAMED &TEDIS&AFRICA'!L14 -> 68 | M14: =L14*C14 -> 134.64 | N14: ='BAMAKO POOL-LABOREX'!N14+'BAMAKO POOL-UBIPHARM'!N14+'BAMAKO POOL-AFRICALA'!N14+'BAMAKO POOL-CAMED &TEDIS&AFRICA'!N14 -> 136 | O14: =N14*C14 -> 269.28 | P14: ='BAMAKO POOL-LABOREX'!R14+'BAMAKO POOL-UBIPHARM'!R14+'BAMAKO POOL-AFRICALA'!R14+'BAMAKO POOL-CAMED &TEDIS&AFRICA'!R14 -> 73 | Q14: =P14*C14 -> 144.54 | R14: =D14+F14+H14+J14+L14+N14++P14 -> 355 | S14: =R14*C14 -> 702.9 | T14: =D14+F14+H14+J14+L14+N14 -> 282 | U14: =T14*$C14 -> 558.36 | V14: =S14/5 -> 140.58 | W14: =U14/4 -> 139.59
A15: 11 | B15: TRACLAV1125 | C15: 4.69 | D15: ='BAMAKO POOL-LABOREX'!D15+'BAMAKO POOL-UBIPHARM'!D15+'BAMAKO POOL-AFRICALA'!D15+'BAMAKO POOL-CAMED &TEDIS&AFRICA'!D15 -> 0 | E15: =D15*C15 -> 0 | F15: ='BAMAKO POOL-LABOREX'!F15+'BAMAKO POOL-UBIPHARM'!F15+'BAMAKO POOL-AFRICALA'!F15+'BAMAKO POOL-CAMED &TEDIS&AFRICA'!F15 -> 0 | G15: =F15*C15 -> 0 | H15: ='BAMAKO POOL-LABOREX'!H15+'BAMAKO POOL-UBIPHARM'!H15+'BAMAKO POOL-AFRICALA'!H15+'BAMAKO POOL-CAMED &TEDIS&AFRICA'!H15 -> 0 | I15: =H15*C15 -> 0 | J15: ='BAMAKO POOL-LABOREX'!J15+'BAMAKO POOL-UBIPHARM'!J15+'BAMAKO POOL-AFRICALA'!J15+'BAMAKO POOL-CAMED &TEDIS&AFRICA'!J15 -> 0 | K15: =J15*C15 -> 0 | L15: ='BAMAKO POOL-LABOREX'!L15+'BAMAKO POOL-UBIPHARM'!L15+'BAMAKO POOL-AFRICALA'!L15+'BAMAKO POOL-CAMED &TEDIS&AFRICA'!L15 -> 0 | M15: =L15*C15 -> 0 | N15: ='BAMAKO POOL-LABOREX'!N15+'BAMAKO POOL-UBIPHARM'!N15+'BAMAKO POOL-AFRICALA'!N15+'BAMAKO POOL-CAMED &TEDIS&AFRICA'!N15 -> 0 | O15: =N15*C15 -> 0 | P15: ='BAMAKO POOL-LABOREX'!R15+'BAMAKO POOL-UBIPHARM'!R15+'BAMAKO POOL-AFRICALA'!R15+'BAMAKO POOL-CAMED &TEDIS&AFRICA'!R15 -> 0 | Q15: =P15*C15 -> 0 | R15: =D15+F15+H15+J15+L15+N15++P15 -> 0 | S15: =R15*C15 -> 0 | T15: =D15+F15+H15+J15+L15+N15 -> 0 | U15: =T15*$C15 -> 0 | V15: =S15/5 -> 0 | W15: =U15/4 -> 0
A16: 12 | B16: TRACLAV 625 | C16: 2.9 | D16: ='BAMAKO POOL-LABOREX'!D16+'BAMAKO POOL-UBIPHARM'!D16+'BAMAKO POOL-AFRICALA'!D16+'BAMAKO POOL-CAMED &TEDIS&AFRICA'!D16 -> 0 | E16: =D16*C16 -> 0 | F16: ='BAMAKO POOL-LABOREX'!F16+'BAMAKO POOL-UBIPHARM'!F16+'BAMAKO POOL-AFRICALA'!F16+'BAMAKO POOL-CAMED &TEDIS&AFRICA'!F16 -> 0 | G16: =F16*C16 -> 0 | H16: ='BAMAKO POOL-LABOREX'!H16+'BAMAKO POOL-UBIPHARM'!H16+'BAMAKO POOL-AFRICALA'!H16+'BAMAKO POOL-CAMED &TEDIS&AFRICA'!H16 -> 0 | I16: =H16*C16 -> 0 | J16: ='BAMAKO POOL-LABOREX'!J16+'BAMAKO POOL-UBIPHARM'!J16+'BAMAKO POOL-AFRICALA'!J16+'BAMAKO POOL-CAMED &TEDIS&AFRICA'!J16 -> 0 | K16: =J16*C16 -> 0 | L16: ='BAMAKO POOL-LABOREX'!L16+'BAMAKO POOL-UBIPHARM'!L16+'BAMAKO POOL-AFRICALA'!L16+'BAMAKO POOL-CAMED &TEDIS&AFRICA'!L16 -> 0 | M16: =L16*C16 -> 0 | N16: ='BAMAKO POOL-LABOREX'!N16+'BAMAKO POOL-UBIPHARM'!N16+'BAMAKO POOL-AFRICALA'!N16+'BAMAKO POOL-CAMED &TEDIS&AFRICA'!N16 -> 0 | O16: =N16*C16 -> 0 | P16: ='BAMAKO POOL-LABOREX'!R16+'BAMAKO POOL-UBIPHARM'!R16+'BAMAKO POOL-AFRICALA'!R16+'BAMAKO POOL-CAMED &TEDIS&AFRICA'!R16 -> 0 | Q16: =P16*C16 -> 0 | R16: =D16+F16+H16+J16+L16+N16++P16 -> 0 | S16: =R16*C16 -> 0 | T16: =D16+F16+H16+J16+L16+N16 -> 0 | U16: =T16*$C16 -> 0 | V16: =S16/5 -> 0 | W16: =U16/4 -> 0
... A21: 17 | B21: TUMI | C21: 2 | D21: ='BAMAKO POOL-LABOREX'!D21+'BAMAKO POOL-UBIPHARM'!D21+'BAMAKO POOL-AFRICALA'!D21+'BAMAKO POOL-CAMED &TEDIS&AFRICA'!D21 -> 0 | E21: =D21*C21 -> 0 | F21: ='BAMAKO POOL-LABOREX'!F21+'BAMAKO POOL-UBIPHARM'!F21+'BAMAKO POOL-AFRICALA'!F21+'BAMAKO POOL-CAMED &TEDIS&AFRICA'!F21 -> 0 | G21: =F21*C21 -> 0 | H21: ='BAMAKO POOL-LABOREX'!H21+'BAMAKO POOL-UBIPHARM'!H21+'BAMAKO POOL-AFRICALA'!H21+'BAMAKO POOL-CAMED &TEDIS&AFRICA'!H21 -> 0 | I21: =H21*C21 -> 0 | J21: ='BAMAKO POOL-LABOREX'!J21+'BAMAKO POOL-UBIPHARM'!J21+'BAMAKO POOL-AFRICALA'!J21+'BAMAKO POOL-CAMED &TEDIS&AFRICA'!J21 -> 0 | K21: =J21*C21 -> 0 | L21: ='BAMAKO POOL-LABOREX'!L21+'BAMAKO POOL-UBIPHARM'!L21+'BAMAKO POOL-AFRICALA'!L21+'BAMAKO POOL-CAMED &TEDIS&AFRICA'!L21 -> 0 | M21: =L21*C21 -> 0 | N21: ='BAMAKO POOL-LABOREX'!N21+'BAMAKO POOL-UBIPHARM'!N21+'BAMAKO POOL-AFRICALA'!N21+'BAMAKO POOL-CAMED &TEDIS&AFRICA'!N21 -> 0 | O21: =N21*C21 -> 0 | P21: ='BAMAKO POOL-LABOREX'!R21+'BAMAKO POOL-UBIPHARM'!R21+'BAMAKO POOL-AFRICALA'!R21+'BAMAKO POOL-CAMED &TEDIS&AFRICA'!R21 -> 0 | Q21: =P21*C21 -> 0 | R21: =D21+F21+H21+J21+L21+N21++P21 -> 0 | S21: =R21*C21 -> 0 | T21: =D21+F21+H21+J21+L21+N21 -> 0 | U21: =T21*$C21 -> 0 | V21: =S21/5 -> 0 | W21: =U21/4 -> 0
B22: TOTAL | E22: =SUM(E5:E21) -> 2301.33 | G22: =SUM(G5:G21) -> 701.25 | I22: =SUM(I5:I21) -> 2345.22 | K22: =SUM(K5:K21) -> 843 | M22: =SUM(M5:M21) -> 3743.11 | O22: =SUM(O5:O21) -> 7362.47 | Q22: =SUM(Q5:Q21) -> 6837 | S22: =SUM(S5:S21) -> 24133.38 | U22: =SUM(U5:U21) -> 17296.38 | V22: =S22/5 -> 4826.676 | W22: =U22/4 -> 4324.095

Sheet OUTSTATION-AFRICA LAB 
A2: MONTH | B2: 45261
D3: KAYE | F3: KITA | H3: KOULIKORO | J3: SAN | L3: KEGNEBA | N3: BOUGOUNI | P3: SIKASSO | R3: SEGOU | T3: KUTIALLA | V3: MOPTI | X3: TOTAL
B4: PRODUCT NAME | C4: CIF | D4: Unit | E4: value | F4: Unit | G4: value | H4: Unit | I4: Value | J4: Unit | K4: Value | L4: Unit | M4: Value | N4: Unit | O4: Value | P4: Unit | Q4: Value | R4: Unit | S4: Value | T4: Unit | U4: Value | V4: Unit | W4: Value | X4: Unit | Y4: Value
A5: 1 | B5: AQUANATE | C5: 0.99 | E5: =D5*C5 -> 0 | G5: =F5*C5 -> 0 | I5: =C5*H5 -> 0 | K5: =J5*C5 -> 0 | M5: =L5*A5 -> 0 | O5: =N5*C5 -> 0 | Q5: =P5*C5 -> 0 | S5: =R5*C5 -> 0 | U5: =T5*C5 -> 0 | W5: =V5*C5 -> 0 | X5: =D5+F5+H5+J5+L5+N5+P5+R5+T5+V5 -> 0 | Y5: =X5*C5 -> 0
A6: 2 | B6: BACTOXIME SYRP | C6: 2.29 | E6: =D6*C6 -> 0 | G6: =F6*C6 -> 0 | I6: =C6*H6 -> 0 | K6: =J6*C6 -> 0 | M6: =L6*A6 -> 0 | O6: =N6*C6 -> 0 | Q6: =P6*C6 -> 0 | S6: =R6*C6 -> 0 | U6: =T6*C6 -> 0 | W6: =V6*C6 -> 0 | X6: =D6+F6+H6+J6+L6+N6+P6+R6+T6+V6 -> 0 | Y6: =X6*C6 -> 0
A7: 3 | B7: BACTOXIME 200 | C7: 3.66 | E7: =D7*C7 -> 0 | G7: =F7*C7 -> 0 | I7: =C7*H7 -> 0 | K7: =J7*C7 -> 0 | M7: =L7*A7 -> 0 | O7: =N7*C7 -> 0 | Q7: =P7*C7 -> 0 | S7: =R7*C7 -> 0 | U7: =T7*C7 -> 0 | W7: =V7*C7 -> 0 | X7: =D7+F7+H7+J7+L7+N7+P7+R7+T7+V7 -> 0 | Y7: =X7*C7 -> 0
A8: 4 | B8: ESOPRA 20 | C8: 2.81 | E8: =D8*C8 -> 0 | G8: =F8*C8 -> 0 | I8: =C8*H8 -> 0 | K8: =J8*C8 -> 0 | M8: =L8*A8 -> 0 | O8: =N8*C8 -> 0 | Q8: =P8*C8 -> 0 | S8: =R8*C8 -> 0 | U8: =T8*C8 -> 0 | W8: =V8*C8 -> 0 | X8: =D8+F8+H8+J8+L8+N8+P8+R8+T8+V8 -> 0 | Y8: =X8*C8 -> 0
A9: 5 | B9: ESOPRA 40 | C9: 3.46 | E9: =D9*C9 -> 0 | G9: =F9*C9 -> 0 | I9: =C9*H9 -> 0 | K9: =J9*C9 -> 0 | M9: =L9*A9 -> 0 | O9: =N9*C9 -> 0 | Q9: =P9*C9 -> 0 | S9: =R9*C9 -> 0 | U9: =T9*C9 -> 0 | W9: =V9*C9 -> 0 | X9: =D9+F9+H9+J9+L9+N9+P9+R9+T9+V9 -> 0 | Y9: =X9*C9 -> 0
A10: 6 | B10: METAREN | C10: 1.06 | E10: =D10*C10 -> 0 | G10: =F10*C10 -> 0 | I10: =C10*H10 -> 0 | K10: =J10*C10 -> 0 | M10: =L10*A10 -> 0 | O10: =N10*C10 -> 0 | Q10: =P10*C10 -> 0 | S10: =R10*C10 -> 0 | U10: =T10*C10 -> 0 | W10: =V10*C10 -> 0 | X10: =D10+F10+H10+J10+L10+N10+P10+R10+T10+V10 -> 0 | Y10: =X10*C10 -> 0
A11: 7 | B11: DIP3 | C11: 3.63 | E11: =D11*C11 -> 0 | G11: =F11*C11 -> 0 | I11: =C11*H11 -> 0 | K11: =J11*C11 -> 0 | M11: =L11*A11 -> 0 | O11: =N11*C11 -> 0 | Q11: =P11*C11 -> 0 | S11: =R11*C11 -> 0 | U11: =T11*C11 -> 0 | W11: =V11*C11 -> 0 | X11: =D11+F11+H11+J11+L11+N11+P11+R11+T11+V11 -> 0 | Y11: =X11*C11 -> 0
A12: 8 | B12: PALUCURE 20/120 | C12: 0.85 | E12: =D12*C12 -> 0 | G12: =F12*C12 -> 0 | I12: =C12*H12 -> 0 | K12: =J12*C12 -> 0 | M12: =L12*A12 -> 0 | O12: =N12*C12 -> 0 | Q12: =P12*C12 -> 0 | S12: =R12*C12 -> 0 | U12: =T12*C12 -> 0 | W12: =V12*C12 -> 0 | X12: =D12+F12+H12+J12+L12+N12+P12+R12+T12+V12 -> 0 | Y12: =X12*C12 -> 0
A13: 9 | B13: PALUCURE 80/480 | C13: 1.98 | E13: =D13*C13 -> 0 | G13: =F13*C13 -> 0 | I13: =C13*H13 -> 0 | K13: =J13*C13 -> 0 | M13: =L13*A13 -> 0 | O13: =N13*C13 -> 0 | Q13: =P13*C13 -> 0 | S13: =R13*C13 -> 0 | U13: =T13*C13 -> 0 | W13: =V13*C13 -> 0 | X13: =D13+F13+H13+J13+L13+N13+P13+R13+T13+V13 -> 0 | Y13: =X13*C13 -> 0
A14: 10 | B14: PALUCURE 40/240 | C14: 1.98 | E14: =D14*C14 -> 0 | G14: =F14*C14 -> 0 | I14: =C14*H14 -> 0 | K14: =J14*C14 -> 0 | M14: =L14*A14 -> 0 | O14: =N14*C14 -> 0 | Q14: =P14*C14 -> 0 | S14: =R14*C14 -> 0 | U14: =T14*C14 -> 0 | W14: =V14*C14 -> 0 | X14: =D14+F14+H14+J14+L14+N14+P14+R14+T14+V14 -> 0 | Y14: =X14*C14 -> 0
A15: 11 | B15: TRACLAV1125 | C15: 4.69 | E15: =D15*C15 -> 0 | G15: =F15*C15 -> 0 | I15: =C15*H15 -> 0 | K15: =J15*C15 -> 0 | M15: =L15*A15 -> 0 | O15: =N15*C15 -> 0 | Q15: =P15*C15 -> 0 | S15: =R15*C15 -> 0 | U15: =T15*C15 -> 0 | W15: =V15*C15 -> 0 | X15: =D15+F15+H15+J15+L15+N15+P15+R15+T15+V15 -> 0 | Y15: =X15*C15 -> 0
A16: 12 | B16: TRACLAV 625 | C16: 2.9 | E16: =D16*C16 -> 0 | G16: =F16*C16 -> 0 | I16: =C16*H16 -> 0 | K16: =J16*C16 -> 0 | M16: =L16*A16 -> 0 | O16: =N16*C16 -> 0 | Q16: =P16*C16 -> 0 | S16: =R16*C16 -> 0 | U16: =T16*C16 -> 0 | W16: =V16*C16 -> 0 | X16: =D16+F16+H16+J16+L16+N16+P16+R16+T16+V16 -> 0 | Y16: =X16*C16 -> 0
A17: 13 | B17: TRIAF- S | C17: 1.9 | D17: 0 | E17: =D17*C17 -> 0 | F17: 0 | G17: =F17*C17 -> 0 | H17: 0 | I17: =H17*C17 -> 0 | J17: 0 | K17: =J17*C17 -> 0 | L17: 0 | M17: =L17*C17 -> 0 | N17: 0 | O17: =N17*C17 -> 0 | Q17: =P17*C17 -> 0 | R17: 0 | S17: =R17*C17 -> 0
A18: 14 | B18: PALUCURE PLUS 80/480 | C18: 2.4 | D18: 0 | E18: =D18*C18 -> 0 | F18: 0 | G18: =F18*C18 -> 0 | H18: 0 | I18: =H18*C18 -> 0 | J18: 0 | K18: =J18*C18 -> 0 | L18: 0 | M18: =L18*C18 -> 0 | N18: 0 | O18: =N18*C18 -> 0 | Q18: =P18*C18 -> 0 | R18: 0 | S18: =R18*C18 -> 0
A19: 13 | B19: TRACLAV 1.2 | C19: 1.5 | E19: =D19*C19 -> 0 | G19: =F19*C19 -> 0 | I19: =C19*H19 -> 0 | K19: =J19*C19 -> 0 | M19: =L19*A19 -> 0 | O19: =N19*C19 -> 0 | Q19: =P19*C19 -> 0 | S19: =R19*C19 -> 0 | U19: =T19*C19 -> 0 | W19: =V19*C19 -> 0 | X19: =D19+F19+H19+J19+L19+N19+P19+R19+T19+V19 -> 0 | Y19: =X19*C19 -> 0
A20: 16 | B20: TRACLAV1125 SACHT | C20: 5.38 | D20: 0 | E20: =D20*C20 -> 0 | G20: =F20*C20 -> 0 | H20: 0 | I20: =H20*C20 -> 0 | K20: =J20*C20 -> 0 | L20: 0 | M20: =L20*C20 -> 0 | N20: 0 | O20: =N20*C20 -> 0 | Q20: =P20*C20 -> 0 | R20: 0 | S20: =R20*C20 -> 0 | T20: =D20+F20+H20+J20+L20+N20+P20+R20 -> 0 | U20: =T20*C20 -> 0
A21: 17 | B21: TUMI | C21: 2 | D21: 0 | E21: =D21*C21 -> 0 | G21: =F21*A21 -> 0 | H21: 0 | I21: =H21*C21 -> 0 | K21: =J21*C21 -> 0 | L21: 0 | M21: =L21*C21 -> 0 | N21: 0 | O21: =N21*C21 -> 0 | Q21: =P21*C21 -> 0 | R21: 0 | S21: =R21*C21 -> 0 | T21: =D21+F21+H21+J21+L21+N21+P21+R21 -> 0 | U21: =T21*C21 -> 0
B22: TOTAL | E22: =SUM(E5:E19) -> 0 | G22: =SUM(G5:G19) -> 0 | K22: =SUM(K5:K19) -> 0 | Q22: =SUM(Q5:Q19) -> 0 | S22: =SUM(S5:S19) -> 0 | T22: 0 | U22: =SUM(U5:U19) -> 0 | W22: =SUM(W5:W19) -> 0 | Y22: =E22+G22+I22+K22+M22+O22+Q22+S22+U22+W22 -> 0

Sheet UBIPHARM-OUTSTATION
A2: MONTH | B2: 45597
D3: KAYES | F3: KITA | H3: KOULIKORO | J3: SAN | L3: KENIGBA | N3: BOUGOUNI | P3: SIKASSO | R3: SEGOU | T3: KUTIALLA | V3: MOPTI | X3: TOTAL
B4: PRODUCT NAME | C4: CIF | D4: Unit | E4: value | F4: Unit | G4: value | H4: Unit | I4: Value | J4: Unit | K4: Value | L4: Unit | M4: Value | N4: Unit | O4: Value | P4: Unit | Q4: Value | R4: Unit | S4: Value | T4: Unit | U4: Value | V4: Unit | W4: Value | X4: Unit | Y4: Value
A5: 1 | B5: AQUANATE | C5: 0.99 | D5: 600 | E5: =D5*C5 -> 594 | F5: 50 | G5: =F5*C5 -> 49.5 | H5: 69 | I5: =C5*H5 -> 68.31 | J5: 224 | K5: =J5*C5 -> 221.76 | L5: 48 | M5: =L5*C5 -> 47.52 | N5: 65 | O5: =N5*C5 -> 64.35 | P5: 400 | Q5: =P5*C5 -> 396 | R5: 300 | S5: =R5*C5 -> 297 | T5: 100 | U5: =T5*C5 -> 99 | V5: 5930 | W5: =V5*C5 -> 5870.7 | X5: =D5+F5+H5+J5+L5+N5+P5+R5+T5+V5 -> 7786 | Y5: =X5*C5 -> 7708.14
A6: 2 | B6: BACTOXIME SYRP | C6: 2.29 | D6: 10 | E6: =D6*C6 -> 22.9 | F6: 0 | G6: =F6*C6 -> 0 | H6: 0 | I6: =C6*H6 -> 0 | J6: 0 | K6: =J6*C6 -> 0 | L6: 0 | M6: =L6*C6 -> 0 | N6: 1 | O6: =N6*C6 -> 2.29 | P6: 2 | Q6: =P6*C6 -> 4.58 | R6: 4 | S6: =R6*C6 -> 9.16 | T6: 4 | U6: =T6*C6 -> 9.16 | V6: 0 | W6: =V6*C6 -> 0 | X6: =D6+F6+H6+J6+L6+N6+P6+R6+T6+V6 -> 21 | Y6: =X6*C6 -> 48.09
A7: 3 | B7: BACTOXIME 200 | C7: 3.66 | D7: 200 | E7: =D7*C7 -> 732 | F7: 66 | G7: =F7*C7 -> 241.56 | H7: 85 | I7: =C7*H7 -> 311.1 | J7: 181 | K7: =J7*C7 -> 662.46 | L7: 50 | M7: =L7*C7 -> 183 | N7: 40 | O7: =N7*C7 -> 146.4 | P7: 138 | Q7: =P7*C7 -> 505.08 | R7: 200 | S7: =R7*C7 -> 732 | T7: 60 | U7: =T7*C7 -> 219.6 | V7: 80 | W7: =V7*C7 -> 292.8 | X7: =D7+F7+H7+J7+L7+N7+P7+R7+T7+V7 -> 1100 | Y7: =X7*C7 -> 4026
A8: 4 | B8: ESOPRA 20 | C8: 2.81 | D8: 15 | E8: =D8*C8 -> 42.15 | F8: 5 | G8: =F8*C8 -> 14.05 | H8: 10 | I8: =C8*H8 -> 28.1 | J8: 0 | K8: =J8*C8 -> 0 | L8: 3 | M8: =L8*C8 -> 8.43 | N8: 6 | O8: =N8*C8 -> 16.86 | P8: 10 | Q8: =P8*C8 -> 28.1 | R8: 4 | S8: =R8*C8 -> 11.24 | T8: 7 | U8: =T8*C8 -> 19.67 | V8: 11 | W8: =V8*C8 -> 30.91 | X8: =D8+F8+H8+J8+L8+N8+P8+R8+T8+V8 -> 71 | Y8: =X8*C8 -> 199.51
